Workbook

Sheet Router
A1: =Specs!B1 -> Router | B1: Requirement | C1: {=INDEX(D1:AP1, MATCH(1, D16:AP16, 0))} -> C8500-12X | D1: C1161-8P | E1: C1161X-8P | F1: C1131-8PWS | G1: C1131X-8PWS | H1: C1121-4P | I1: C1121-8P | J1: C1127-8PLTEP | K1: C1116-4P | L1: C1117-4P | M1: C1112-8P | N1: C1109-4PLTE2P | O1: C8200L-1N-4T | P1: C8200-1N-4T | Q1: C8300-1N1S-6T | R1: C8300-2N2S-6T | S1: C8300-1N1S-4T2X | T1: C8300-2N2S-4T2X | U1: C8500L-8S4X | V1: C8500-12X | W1: C8500-12X4QC | X1: C8500-20X6C
A2: =Specs!B2 -> Throughput (Mbps) | B2: =IFERROR(__xludf.DUMMYFUNCTION("IMPORTRANGE(""https://docs.google.com/spreadsheets/d/18TjePryHG687L54fIGU6Od12DGyT3mPoblPemZTZRY4"",""Router!B3:B10"")"),5000.0) -> 5000 | C2: =hlookup($C$1,$D$1:$AP$10,2,0) -> 51000 | D2: 1889 | E2: 1889 | F2: 1889 | G2: 1889 | H2: 1426 | I2: 1889 | J2: 1889 | K2: 1889 | L2: 1889 | M2: 1889 | N2: 1169 | O2: 500 | P2: 1000 | Q2: 2000 | R2: 2000 | S2: 17000 | T2: 18800 | U2: 19000 | V2: 51000 | W2: 96000 | X2: 350000
A3: =Specs!B3 -> Số lượng cổng WAN 1GE | C3: =hlookup($C$1,$D$1:$AP$10,3,0) -> 12 | D3: 2 | E3: 2 | F3: 2 | G3: 2 | H3: 2 | I3: 2 | J3: 1 | K3: 1 | L3: 1 | M3: 1 | N3: 1 | O3: 4 | P3: 4 | Q3: 6 | R3: 6 | S3: 4 | T3: 4 | U3: 8 | V3: 12 | W3: 12 | X3: 20
A4: =Specs!B4 -> Số lượng cổng WAN 10GE | C4: =hlookup($C$1,$D$1:$AP$10,4,0) -> 12 | D4: 0 | E4: 0 | F4: 0 | G4: 0 | H4: 0 | I4: 0 | J4: 0 | K4: 0 | L4: 0 | M4: 0 | N4: 0 | S4: 2 | T4: 2 | U4: 4 | V4: 12 | W4: 12 | X4: 20
A5: =Specs!B5 -> Số lượng cổng LAN 1GE | C5: =hlookup($C$1,$D$1:$AP$10,5,0) | D5: 8 | E5: 8 | F5: 8 | G5: 8 | H5: 4 | I5: 8 | J5: 8 | K5: 4 | L5: 4 | M5: 8 | N5: 4 | O5: 8 | P5: 8 | Q5: 8 | R5: 16 | S5: 8 | T5: 16
A6: =Specs!B6 | C6: =hlookup($C$1,$D$1:$AP$10,6,0)
A7: =Specs!B7 | C7: =hlookup($C$1,$D$1:$AP$10,7,0)
A8: =Specs!B8 | C8: =hlookup($C$1,$D$1:$AP$10,8,0)
A9: =Specs!B9 | C9: =hlookup($C$1,$D$1:$AP$10,9,0)
A10: =Specs!B10 | C10: =hlookup($C$1,$D$1:$AP$10,10,0)
A11: Router Class | C11: =hlookup($C$1,$D$1:$AP$11,11,0) -> High End | D11: Low End | E11: Low End | F11: Low End | G11: Low End | H11: Low End | I11: Low End | J11: Low End | K11: Low End | L11: Low End | M11: Low End | N11: Low End | O11: Mid Range | P11: Mid Range | Q11: Mid Range | R11: Mid Range | S11: Mid Range | T11: Mid Range | U11: High End | V11: High End | W11: High End | X11: High End
A13: Số tiêu chí đáp ứng | C13: =sum(1*(C2>=$B$2)+1*(C3>=$B$3)+1*(C4>=$B$4)+1*(C5>=$B$5)) -> 4 | D13: =sum(1*(D2>=$B$2)+1*(D3>=$B$3)+1*(D4>=$B$4)+1*(D5>=$B$5)) -> 3 | E13: =sum(1*(E2>=$B$2)+1*(E3>=$B$3)+1*(E4>=$B$4)+1*(E5>=$B$5)) -> 3 | F13: =sum(1*(F2>=$B$2)+1*(F3>=$B$3)+1*(F4>=$B$4)+1*(F5>=$B$5)) -> 3 | G13: =sum(1*(G2>=$B$2)+1*(G3>=$B$3)+1*(G4>=$B$4)+1*(G5>=$B$5)) -> 3 | H13: =sum(1*(H2>=$B$2)+1*(H3>=$B$3)+1*(H4>=$B$4)+1*(H5>=$B$5)) -> 3 | I13: =sum(1*(I2>=$B$2)+1*(I3>=$B$3)+1*(I4>=$B$4)+1*(I5>=$B$5)) -> 3 | J13: =sum(1*(J2>=$B$2)+1*(J3>=$B$3)+1*(J4>=$B$4)+1*(J5>=$B$5)) -> 3 | ... X13: =sum(1*(X2>=$B$2)+1*(X3>=$B$3)+1*(X4>=$B$4)+1*(X5>=$B$5)) -> 4
A14: Giá dự toán | C14: =iferror(vlookup(C1,Cisco!$A$2:$D$1000,4,0),0) -> 1000 | D14: =iferror(vlookup(D1,Cisco!$A$2:$D$1000,4,0),0) -> 9713.63 | E14: =iferror(vlookup(E1,Cisco!$A$2:$D$1000,4,0),0) -> 10265.06 | F14: =iferror(vlookup(F1,Cisco!$A$2:$D$1000,4,0),0) -> 8922.97 | G14: =iferror(vlookup(G1,Cisco!$A$2:$D$1000,4,0),0) -> 9142.75 | H14: =iferror(vlookup(H1,Cisco!$A$2:$D$1000,4,0),0) -> 8003.55 | I14: =iferror(vlookup(I1,Cisco!$A$2:$D$1000,4,0),0) -> 8311.31 | J14: =iferror(vlookup(J1,Cisco!$A$2:$D$1000,4,0),0) -> 8935.48 | ... X14: =iferror(vlookup(X1,Cisco!$A$2:$D$1000,4,0),0) -> 553572.06
A15: Thiết bị đáp ứng sát nhất số lượng tiêu chí YCKT | C15: =1*(C13=max($D$13:$AP$13)) -> 1 | D15: =1*(D13=max($D$13:$AP$13)) -> 0 | E15: =1*(E13=max($D$13:$AP$13)) -> 0 | F15: =1*(F13=max($D$13:$AP$13)) -> 0 | G15: =1*(G13=max($D$13:$AP$13)) -> 0 | H15: =1*(H13=max($D$13:$AP$13)) -> 0 | I15: =1*(I13=max($D$13:$AP$13)) -> 0 | J15: =1*(J13=max($D$13:$AP$13)) -> 0 | ... X15: =1*(X13=max($D$13:$AP$13)) -> 1
A16: Thiết bị giá tốt nhất đáp ứng | C16: =C15*(C14=minifs($D$14:$AP$14,$D$15:$AP$15,1)) -> 1 | D16: =D15*(D14=minifs($D$14:$AP$14,$D$15:$AP$15,1)) -> 0 | E16: =E15*(E14=minifs($D$14:$AP$14,$D$15:$AP$15,1)) -> 0 | F16: =F15*(F14=minifs($D$14:$AP$14,$D$15:$AP$15,1)) -> 0 | G16: =G15*(G14=minifs($D$14:$AP$14,$D$15:$AP$15,1)) -> 0 | H16: =H15*(H14=minifs($D$14:$AP$14,$D$15:$AP$15,1)) -> 0 | I16: =I15*(I14=minifs($D$14:$AP$14,$D$15:$AP$15,1)) -> 0 | J16: =J15*(J14=minifs($D$14:$AP$14,$D$15:$AP$15,1)) -> 0 | ... X16: =X15*(X14=minifs($D$14:$AP$14,$D$15:$AP$15,1)) -> 0
A17: Thiết bị khác đáp ứng | C17: =(1-($C$1=C1))*(C15=1) -> 0 | D17: =(1-($C$1=D1))*(D15=1) -> 0 | E17: =(1-($C$1=E1))*(E15=1) -> 0 | F17: =(1-($C$1=F1))*(F15=1) -> 0 | G17: =(1-($C$1=G1))*(G15=1) -> 0 | H17: =(1-($C$1=H1))*(H15=1) -> 0 | I17: =(1-($C$1=I1))*(I15=1) -> 0 | J17: =(1-($C$1=J1))*(J15=1) -> 0 | ... X17: =(1-($C$1=X1))*(X15=1) -> 1
A19: Các lựa chọn khác | C19: =IFERROR(__xludf.DUMMYFUNCTION("iferror(filter(D1:AP1,$D$17:$AP$17=1),"""")"),"C8300-1N1S-4T2X") -> C8300-1N1S-4T2X | D19: =IFERROR(__xludf.DUMMYFUNCTION("""COMPUTED_VALUE"""),"C8300-2N2S-4T2X") -> C8300-2N2S-4T2X | E19: =IFERROR(__xludf.DUMMYFUNCTION("""COMPUTED_VALUE"""),"C8500L-8S4X") -> C8500L-8S4X | F19: =IFERROR(__xludf.DUMMYFUNCTION("""COMPUTED_VALUE"""),"C8500-12X4QC") -> C8500-12X4QC | G19: =IFERROR(__xludf.DUMMYFUNCTION("""COMPUTED_VALUE"""),"C8500-20X6C") -> C8500-20X6C
A20: =A2 -> Throughput (Mbps) | C20: =IFERROR(__xludf.DUMMYFUNCTION("iferror(filter(D2:AP2,$D$17:$AP$17=1),"""")"),17000.0) -> 17000 | D20: =IFERROR(__xludf.DUMMYFUNCTION("""COMPUTED_VALUE"""),18800.0) -> 18800 | E20: =IFERROR(__xludf.DUMMYFUNCTION("""COMPUTED_VALUE"""),19000.0) -> 19000 | F20: =IFERROR(__xludf.DUMMYFUNCTION("""COMPUTED_VALUE"""),96000.0) -> 96000 | G20: =IFERROR(__xludf.DUMMYFUNCTION("""COMPUTED_VALUE"""),350000.0) -> 350000
A21: =A3 -> Số lượng cổng WAN 1GE | C21: =IFERROR(__xludf.DUMMYFUNCTION("iferror(filter(D3:AP3,$D$17:$AP$17=1),"""")"),4.0) -> 4 | D21: =IFERROR(__xludf.DUMMYFUNCTION("""COMPUTED_VALUE"""),4.0) -> 4 | E21: =IFERROR(__xludf.DUMMYFUNCTION("""COMPUTED_VALUE"""),8.0) -> 8 | F21: =IFERROR(__xludf.DUMMYFUNCTION("""COMPUTED_VALUE"""),12.0) -> 12 | G21: =IFERROR(__xludf.DUMMYFUNCTION("""COMPUTED_VALUE"""),20.0) -> 20
A22: =A4 -> Số lượng cổng WAN 10GE | C22: =IFERROR(__xludf.DUMMYFUNCTION("iferror(filter(D4:AP4,$D$17:$AP$17=1),"""")"),2.0) -> 2 | D22: =IFERROR(__xludf.DUMMYFUNCTION("""COMPUTED_VALUE"""),2.0) -> 2 | E22: =IFERROR(__xludf.DUMMYFUNCTION("""COMPUTED_VALUE"""),4.0) -> 4 | F22: =IFERROR(__xludf.DUMMYFUNCTION("""COMPUTED_VALUE"""),12.0) -> 12 | G22: =IFERROR(__xludf.DUMMYFUNCTION("""COMPUTED_VALUE"""),20.0) -> 20
A23: =A5 -> Số lượng cổng LAN 1GE | C23: =IFERROR(__xludf.DUMMYFUNCTION("iferror(filter(D5:AP5,$D$17:$AP$17=1),"""")"),8.0) -> 8 | D23: =IFERROR(__xludf.DUMMYFUNCTION("""COMPUTED_VALUE"""),16.0) -> 16
A24: Router Class | C24: =IFERROR(__xludf.DUMMYFUNCTION("iferror(filter(D11:AP11,$D$17:$AP$17=1),"""")"),"Mid Range") -> Mid Range | D24: =IFERROR(__xludf.DUMMYFUNCTION("""COMPUTED_VALUE"""),"Mid Range") -> Mid Range | E24: =IFERROR(__xludf.DUMMYFUNCTION("""COMPUTED_VALUE"""),"High End") -> High End | F24: =IFERROR(__xludf.DUMMYFUNCTION("""COMPUTED_VALUE"""),"High End") -> High End | G24: =IFERROR(__xludf.DUMMYFUNCTION("""COMPUTED_VALUE"""),"High End") -> High End

Sheet SwitchCampus
A1: =Specs!C1 -> SwitchCampus | B1: Requirement | C1: {=INDEX(D1:CY1, MATCH(1, D16:CY16, 0))} -> C9500-48Y4C | D1: C1300-8T-E-2G | E1: C1300-8P-E-2G | F1: C1300-8FP-2G | G1: C1300-16T-2G | H1: C1300-16P-2G | I1: C1300-16FP-2G | J1: C1300-24T-4G | K1: C1300-24P-4G | L1: C1300-24FP-4G | M1: C1300-48T-4G | N1: C1300-48P-4G | O1: C1300-48FP-4G | P1: C1300-16P-4X | Q1: C1300-24T-4X | R1: C1300-24P-4X | S1: C1300-24FP-4X | T1: C1300-48T-4X | U1: C1300-48P-4X | V1: C1300-48FP-4X | W1: C1300-12XT-2X | X1: C1300-12XS | Y1: C1300-16XTS | Z1: C1300-24XS | AA1: C1300-24XT | AB1: C1300-24XTS | AC1: C1300X-24T-4X | AD1: C1300X-48T-4X | AE1: C1300X-24P-4X | AF1: C1300X-48P-4X | AG1: C9200-24T | AH1: C9200-24P | AI1: C9200-48T | AJ1: C9200-48P | AK1: C9200L-24T-4G | AL1: C9200L-24P-4G | AM1: C9200L-48T-4G | AN1: C9200L-48P-4G | AO1: C9200L-24T-4X | AP1: C9200L-24P-4X | AQ1: C9200L-48T-4X | AR1: C9200L-48P-4X | AS1: C9200CX-8P-2X2G | AT1: C9200CX-12T-2X2G | AU1: C9200CX-12P-2X2G | AV1: C9300X-48HX | AW1: C9300X-48TX | AX1: C9300X-48HXN | AY1: C9300X-24HX | AZ1: C9300X-12Y | BA1: C9300X-24Y | BB1: C9300L-24T-4G | BC1: C9300L-24P-4G | BD1: C9300L-24T-4X | BE1: C9300L-24P-4X | BF1: C9300L-48T-4G | BG1: C9300L-48P-4G | BH1: C9300L-48T-4X | BI1: C9300L-48P-4X | BJ1: C9300-24T | BK1: C9300-24P | BL1: C9300-24U | BM1: C9300-24H | BN1: C9300-24S | BO1: C9300-24UB | BP1: C9300-48T | BQ1: C9300-48P | BR1: C9300-48U | BS1: C9300-48H | BT1: C9300-48S | BU1: C9300-48UB | BV1: C9500-32C | BW1: C9500-32QC | BX1: C9500-48Y4C | BY1: C9500-24Y4C | BZ1: C9500X-28C8D | CA1: C9500X-60L4D | CB1: C1200-8T-D | CC1: C1200-8T-E-2G | CD1: C1200-8P-E-2G | CE1: C1200-8FP-2G | CF1: C1200-16T-2G | CG1: C1200-16P-2G | CH1: C1200-24T-4G | CI1: C1200-24P-4G | CJ1: C1200-24FP-4G | CK1: C1200-48T-4G | CL1: C1200-48P-4G | CM1: C1200-24T-4X | CN1: C1200-24P-4X | CO1: C1200-24FP-4X | CP1: C1200-48T-4X | CQ1: C1200-48P-4X | CR1: EX4200-24T | CS1: EX4300-48S | CT1: EX4600
A2: =Specs!C2 -> Switching Bandwidth - Full Duplex (Gbps) | B2: =IFERROR(__xludf.DUMMYFUNCTION("IMPORTRANGE(""https://docs.google.com/spreadsheets/d/18TjePryHG687L54fIGU6Od12DGyT3mPoblPemZTZRY4"",""SwitchCampus!B3:B10"")"),"") | C2: =hlookup($C$1,$D$1:$CY$10,2,0) -> 3200 | D2: 20 | E2: 20 | F2: 20 | G2: 36 | H2: 36 | I2: 36 | J2: 56 | K2: 56 | L2: 56 | M2: 104 | N2: 104 | O2: 104 | P2: 112 | Q2: 128 | R2: 128 | S2: 128 | T2: 176 | U2: 176 | V2: 176 | W2: 280 | X2: 240 | Y2: 320 | Z2: 480 | AA2: 480 | AB2: 480 | AC2: 128 | AD2: 176 | AE2: 128 | AF2: 176 | AG2: 128 | AH2: 128 | AI2: 176 | AJ2: 176 | AK2: 56 | AL2: 56 | AM2: 104 | AN2: 104 | AO2: 128 | AP2: 128 | AQ2: 176 | AR2: 176 | AS2: 60 | AT2: 70 | AU2: 68 | AV2: 1,76 | AW2: 1,76 | AX2: 960 | AY2: 800 | AZ2: 1 | BA2: 2 | BB2: 56 | BC2: 56 | BD2: 128 | BE2: 128 | BF2: 104 | BG2: 104 | BH2: 176 | BI2: 176 | BJ2: 208 | BK2: 208 | BL2: 208 | BM2: 208 | BN2: 208 | BO2: 208 | BP2: 256 | BQ2: 256 | BR2: 256 | BS2: 256 | BT2: 256 | BU2: 256 | BV2: 6400 | BW2: 3200 | BX2: 3200 | BY2: 2000 | BZ2: 12000 | CA2: 9200 | CB2: 16 | CC2: 20 | CD2: 20 | CE2: 20 | CF2: 36 | CG2: 36 | CH2: 56 | CI2: 56 | CJ2: 56 | CK2: 104 | CL2: 104 | CM2: 128 | CN2: 128 | CO2: 128 | CP2: 176 | CQ2: 176
A3: =Specs!C3 -> Forwarding Capacity (Mpps) | C3: =hlookup($C$1,$D$1:$CY$10,3,0) -> 1000 | D3: 14.88 | E3: 14.88 | F3: 14.88 | G3: 26.78 | H3: 26.78 | I3: 26.78 | J3: 41.66 | K3: 41.66 | L3: 41.66 | M3: 77.38 | N3: 77.38 | O3: 77.38 | P3: 83.32 | Q3: 95.23 | R3: 95.23 | S3: 95.23 | T3: 130.94 | U3: 130.94 | V3: 130.94 | W3: 208.33 | X3: 178.57 | Y3: 238.1 | Z3: 357.14 | AA3: 357.14 | AB3: 357.12 | AC3: 95.23 | AD3: 130.95 | AE3: 95.23 | AF3: 130.95 | AG3: 95.23 | AH3: 95.23 | AI3: 130.95 | AJ3: 130.95 | AK3: 41.67 | AL3: 41.67 | AM3: 77.38 | AN3: 77.38 | AO3: 95.23 | AP3: 95.23 | AQ3: 130.95 | AR3: 130.95 | AS3: 44.64 | AT3: 52.08 | AU3: 50.59 | AV3: 1309 | AW3: 1309 | AX3: 714.24 | AY3: 654.72 | AZ3: 744.04 | BA3: 1488 | BB3: 41.66 | BC3: 41.66 | BD3: 95.23 | BE3: 95.23 | BF3: 77.38 | BG3: 77.38 | BH3: 130.95 | BI3: 130.95 | BJ3: 154.76 | BK3: 154.76 | BL3: 154.76 | BM3: 154.76 | BN3: 154.76 | BO3: 154.76 | BP3: 190.47 | BQ3: 190.47 | BR3: 190.48 | BS3: 190.48 | BT3: 190.47 | BU3: 190.48 | BV3: 2000 | BW3: 1000 | BX3: 1000 | BY3: 1000 | BZ3: 8000 | CA3: 8000 | CB3: 11.9 | CC3: 14.88 | CD3: 14.88 | CE3: 14.88 | CF3: 26.78 | CG3: 26.78 | CH3: 41.66 | CI3: 41.66 | CJ3: 41.66 | CK3: 77.38 | CL3: 77.38 | CM3: 95.23 | CN3: 95.23 | CO3: 95.23 | CP3: 130.94 | CQ3: 130.94
A4: =Specs!C4 -> Số lượng cổng 1GE đồng | C4: =hlookup($C$1,$D$1:$CY$10,4,0) | D4: 10 | E4: 10 | F4: 10 | G4: 16 | H4: 16 | I4: 16 | J4: 24 | K4: 24 | L4: 24 | M4: 48 | N4: 48 | O4: 48 | P4: 16 | Q4: 24 | R4: 24 | S4: 24 | T4: 48 | U4: 48 | V4: 48 | AC4: 24 | AD4: 48 | AE4: 24 | AF4: 48 | AG4: 24 | AH4: 24 | AI4: 48 | AJ4: 48 | AK4: 24 | AL4: 24 | AM4: 48 | AN4: 48 | AO4: 24 | AP4: 24 | AQ4: 48 | AR4: 48 | AS4: 8 | AT4: 12 | AU4: 12 | AV4: 48 | AW4: 48 | AX4: 48 | AY4: 24 | AZ4: 8 | BA4: 8 | BB4: 24 | BC4: 24 | BD4: 24 | BE4: 24 | BF4: 48 | BG4: 48 | BH4: 48 | BI4: 48 | BJ4: 24 | BK4: 24 | BL4: 24 | BM4: 24 | BO4: 24 | BP4: 48 | BQ4: 48 | BR4: 48 | BS4: 48 | BU4: 48 | CB4: 8 | CC4: 8 | CD4: 8 | CE4: 8 | CF4: 16 | CG4: 16 | CH4: 24 | CI4: 24 | CJ4: 24 | CK4: 48 | CL4: 48 | CM4: 24 | CN4: 24 | CO4: 24 | CP4: 48 | CQ4: 48
A5: =Specs!C5 -> Số lượng cổng 1GE SFP | C5: =hlookup($C$1,$D$1:$CY$10,5,0) -> 48 | D5: 2 | E5: 2 | F5: 2 | G5: 2 | H5: 2 | I5: 2 | J5: 4 | K5: 4 | L5: 4 | M5: 4 | N5: 4 | O5: 4 | W5: 2 | X5: 12 | Y5: 8 | Z5: 24 | AB5: 12 | AC5: 4 | AD5: 4 | AE5: 4 | AF5: 4 | AG5: 4 | AH5: 4 | AI5: 4 | AJ5: 4 | AK5: 4 | AL5: 4 | AM5: 4 | AN5: 4 | AV5: 0 | AW5: 0 | AX5: 0 | AY5: 0 | AZ5: 12 | BA5: 24 | BB5: 4 | BC5: 4 | BD5: 4 | BE5: 4 | BF5: 4 | BG5: 4 | BH5: 4 | BI5: 4 | BJ5: 8 | BK5: 8 | BL5: 8 | BM5: 8 | BN5: 32 | BO5: 8 | BP5: 8 | BQ5: 8 | BR5: 8 | BS5: 8 | BT5: 56 | BU5: 8 | BX5: 48 | BY5: 24 | CC5: 2 | CD5: 2 | CE5: 2 | CF5: 2 | CG5: 2 | CH5: 4 | CI5: 4 | CJ5: 4 | CK5: 4 | CL5: 4
A6: =Specs!C6 -> Số lượng cổng 10GE đồng | C6: =hlookup($C$1,$D$1:$CY$10,6,0) | W6: 12 | X6: 2 | Y6: 8 | Z6: 4 | AA6: 24 | AB6: 12 | AV6: 48 | AW6: 48 | AX6: 16 | AY6: 24 | AZ6: 8 | BA6: 8
A7: =Specs!C7 -> Số lượng cổng 10GE quang | B7: =IFERROR(__xludf.DUMMYFUNCTION("""COMPUTED_VALUE"""),48.0) -> 48 | C7: =hlookup($C$1,$D$1:$CY$10,7,0) -> 48 | P7: 4 | Q7: 4 | R7: 4 | S7: 4 | T7: 4 | U7: 4 | V7: 4 | W7: 2 | X7: 12 | Y7: 8 | Z7: 24 | AA7: 4 | AB7: 12 | AC7: 4 | AD7: 4 | AE7: 4 | AF7: 4 | AG7: 4 | AH7: 4 | AI7: 4 | AJ7: 4 | AO7: 4 | AP7: 4 | AQ7: 4 | AR7: 4 | AS7: 2 | AT7: 2 | AU7: 2 | AV7: 0 | AW7: 0 | AX7: 0 | AY7: 0 | AZ7: 12 | BA7: 24 | BD7: 4 | BE7: 4 | BH7: 4 | BI7: 4 | BJ7: 8 | BK7: 8 | BL7: 8 | BM7: 8 | BN7: 8 | BO7: 8 | BP7: 8 | BQ7: 8 | BR7: 8 | BS7: 8 | BT7: 8 | BU7: 8 | BX7: 48 | BY7: 24 | CA7: 60 | CM7: 4 | CN7: 4 | CO7: 4 | CP7: 4 | CQ7: 4
A8: =Specs!C8 -> Số lượng cổng 100GE | C8: =hlookup($C$1,$D$1:$CY$10,8,0) -> 4 | AV8: 2 | AW8: 2 | AX8: 2 | AY8: 2 | AZ8: 2 | BA8: 2 | BV8: 32 | BW8: 16 | BX8: 4 | BY8: 4 | BZ8: 36 | CA8: 4
A9: =Specs!C9 -> Stacking (Y/N) | C9: =hlookup($C$1,$D$1:$CY$10,9,0) -> Y | P9: Y | Q9: Y | R9: Y | S9: Y | T9: Y | U9: Y | V9: Y | W9: Y | X9: Y | Y9: Y | Z9: Y | AA9: Y | AB9: Y | AC9: Y | AD9: Y | AE9: Y | AF9: Y | AG9: Y | AH9: Y | AI9: Y | AJ9: Y | AK9: Y | AL9: Y | AM9: Y | AN9: Y | AO9: Y | AP9: Y | AQ9: Y | AR9: Y | AV9: Y | AW9: Y | AX9: Y | AY9: Y | AZ9: Y | BA9: Y | BB9: Y | BC9: Y | BD9: Y | BE9: Y | BF9: Y | BG9: Y | BH9: Y | BI9: Y | BJ9: Y | BK9: Y | BL9: Y | BM9: Y | BN9: Y | BO9: Y | BP9: Y | BQ9: Y | BR9: Y | BS9: Y | BT9: Y | BU9: Y | BV9: Y | BW9: Y | BX9: Y | BY9: Y | BZ9: Y | CA9: Y | CB9: N | CC9: N | CD9: N | CE9: N | CF9: N | CG9: N | CH9: N | CI9: N | CJ9: N | CK9: N | CL9: N | CM9: N | CN9: N | CO9: N | CP9: N | CQ9: N
A10: =Specs!C10 -> PoE (Y/N) | C10: =hlookup($C$1,$D$1:$CY$10,10,0) | E10: Y | F10: Y | H10: Y | I10: Y | K10: Y | L10: Y | N10: Y | O10: Y | P10: Y | R10: Y | S10: Y | U10: Y | V10: Y | AE10: Y | AF10: Y | AH10: Y | AJ10: Y | AL10: Y | AN10: Y | AP10: Y | AR10: Y | AS10: Y | AU10: Y | AV10: Y | AW10: N | AX10: Y | AY10: Y | AZ10: N | BA10: N | BC10: Y | BE10: Y | BG10: Y | BI10: Y | BK10: Y | BL10: Y | BM10: Y | BO10: Y | BQ10: Y | BR10: Y | BS10: Y | BU10: Y | CB10: N | CC10: N | CD10: Y | CE10: Y | CF10: N | CG10: Y | CH10: N | CI10: Y | CJ10: Y | CK10: N | CL10: Y | CM10: N | CN10: Y | CO10: Y | CP10: N | CQ10: Y
A11: Switch Class | C11: =hlookup($C$1,$D$1:$CY$11,11,0) -> High End | D11: Low End | E11: Low End | F11: Low End | G11: Low End | H11: Low End | I11: Low End | J11: Low End | K11: Low End | L11: Low End | M11: Low End | N11: Low End | O11: Low End | P11: Low End | Q11: Low End | R11: Low End | S11: Low End | T11: Low End | U11: Low End | V11: Low End | W11: Low End | X11: Low End | Y11: Low End | Z11: Low End | AA11: Low End | AB11: Low End | AC11: Low End | AD11: Low End | AE11: Low End | AF11: Low End | AG11: Mid Range | AH11: Mid Range | AI11: Mid Range | AJ11: Mid Range | AK11: Mid Range | AL11: Mid Range | AM11: Mid Range | AN11: Mid Range | AO11: Mid Range | AP11: Mid Range | AQ11: Mid Range | AR11: Mid Range | AS11: Mid Range | AT11: Mid Range | AU11: Mid Range | AV11: High End | AW11: High End | AX11: High End | AY11: High End | AZ11: High End | BA11: High End | BB11: High End | BC11: High End | BD11: High End | BE11: High End | BF11: High End | BG11: High End | BH11: High End | BI11: High End | BJ11: High End | BK11: High End | BL11: High End | BM11: High End | BN11: High End | BO11: High End | BP11: High End | BQ11: High End | BR11: High End | BS11: High End | BT11: High End | BU11: High End | BV11: High End | BW11: High End | BX11: High End | BY11: High End | BZ11: High End | CA11: High End | CB11: Low End | CC11: Low End | CD11: Low End | CE11: Low End | CF11: Low End | CG11: Low End | CH11: Low End | CI11: Low End | CJ11: Low End | CK11: Low End | CL11: Low End | CM11: Low End | CN11: Low End | CO11: Low End | CP11: Low End | CQ11: Low End | CR11: Mid Range | CS11: Mid Range | CT11: High End
A13: Số tiêu chí đáp ứng | C13: =sum(1*(C2>=$B$2)+1*(C3>=$B$3)+1*(C4>=$B$4)+1*(C5>=$B$5)+1*(C6>=$B$6)+1*(C7>=$B$7)+1*(C8>=$B$8)+1*or(C9="Y",$B$9="N",$B$9="")+1*or(C10="Y",$B$10="N",$B$10="")) -> 9 | D13: =sum(1*(D2>=$B$2)+1*(D3>=$B$3)+1*(D4>=$B$4)+1*(D5>=$B$5)+1*(D6>=$B$6)+1*(D7>=$B$7)+1*(D8>=$B$8)+1*or(D9="Y",$B$9="N",$B$9="")+1*or(D10="Y",$B$10="N",$B$10="")) -> 8 | E13: =sum(1*(E2>=$B$2)+1*(E3>=$B$3)+1*(E4>=$B$4)+1*(E5>=$B$5)+1*(E6>=$B$6)+1*(E7>=$B$7)+1*(E8>=$B$8)+1*or(E9="Y",$B$9="N",$B$9="")+1*or(E10="Y",$B$10="N",$B$10="")) -> 8 | F13: =sum(1*(F2>=$B$2)+1*(F3>=$B$3)+1*(F4>=$B$4)+1*(F5>=$B$5)+1*(F6>=$B$6)+1*(F7>=$B$7)+1*(F8>=$B$8)+1*or(F9="Y",$B$9="N",$B$9="")+1*or(F10="Y",$B$10="N",$B$10="")) -> 8 | G13: =sum(1*(G2>=$B$2)+1*(G3>=$B$3)+1*(G4>=$B$4)+1*(G5>=$B$5)+1*(G6>=$B$6)+1*(G7>=$B$7)+1*(G8>=$B$8)+1*or(G9="Y",$B$9="N",$B$9="")+1*or(G10="Y",$B$10="N",$B$10="")) -> 8 | H13: =sum(1*(H2>=$B$2)+1*(H3>=$B$3)+1*(H4>=$B$4)+1*(H5>=$B$5)+1*(H6>=$B$6)+1*(H7>=$B$7)+1*(H8>=$B$8)+1*or(H9="Y",$B$9="N",$B$9="")+1*or(H10="Y",$B$10="N",$B$10="")) -> 8 | I13: =sum(1*(I2>=$B$2)+1*(I3>=$B$3)+1*(I4>=$B$4)+1*(I5>=$B$5)+1*(I6>=$B$6)+1*(I7>=$B$7)+1*(I8>=$B$8)+1*or(I9="Y",$B$9="N",$B$9="")+1*or(I10="Y",$B$10="N",$B$10="")) -> 8 | J13: =sum(1*(J2>=$B$2)+1*(J3>=$B$3)+1*(J4>=$B$4)+1*(J5>=$B$5)+1*(J6>=$B$6)+1*(J7>=$B$7)+1*(J8>=$B$8)+1*or(J9="Y",$B$9="N",$B$9="")+1*or(J10="Y",$B$10="N",$B$10="")) -> 8 | ... CY13: =sum(1*(CY2>=$B$2)+1*(CY3>=$B$3)+1*(CY4>=$B$4)+1*(CY5>=$B$5)+1*(CY6>=$B$6)+1*(CY7>=$B$7)+1*(CY8>=$B$8)+1*or(CY9="Y",$B$9="N",$B$9="")+1*or(CY10="Y",$B$10="N",$B$10="")) -> 8
A14: Giá dự toán | C14: =iferror(vlookup(C1,AllListPrice!$A$2:$D$1000,4,0),0) -> 66036.97 | D14: =iferror(vlookup(D1,AllListPrice!$A$2:$D$1000,4,0),0) -> 463.29 | E14: =iferror(vlookup(E1,AllListPrice!$A$2:$D$1000,4,0),0) -> 570.56 | F14: =iferror(vlookup(F1,AllListPrice!$A$2:$D$1000,4,0),0) -> 757.69 | G14: =iferror(vlookup(G1,AllListPrice!$A$2:$D$1000,4,0),0) -> 655.57 | H14: =iferror(vlookup(H1,AllListPrice!$A$2:$D$1000,4,0),0) -> 952.7 | I14: =iferror(vlookup(I1,AllListPrice!$A$2:$D$1000,4,0),0) -> 1350.49 | J14: =iferror(vlookup(J1,AllListPrice!$A$2:$D$1000,4,0),0) -> 913.34 | ... CX14: =iferror(vlookup(CX1,AllListPrice!$A$2:$D$1000,4,0),0) -> 0 | CY14: =iferror(vlookup(CY1,Cisco!$A$2:$D$1000,4,0),0) -> 0
A15: Thiết bị đáp ứng sát nhất số lượng tiêu chí YCKT | C15: =1*(C13=max($D$13:$CY$13)) -> 1 | D15: =1*(D13=max($D$13:$CY$13)) -> 0 | E15: =1*(E13=max($D$13:$CY$13)) -> 0 | F15: =1*(F13=max($D$13:$CY$13)) -> 0 | G15: =1*(G13=max($D$13:$CY$13)) -> 0 | H15: =1*(H13=max($D$13:$CY$13)) -> 0 | I15: =1*(I13=max($D$13:$CY$13)) -> 0 | J15: =1*(J13=max($D$13:$CY$13)) -> 0 | ... BR15: =1*(BR13=max($D$13:$CY$13)) -> 0 | BS15: =1*(BS13=max($D$13:$CQ$13)) -> 0 | BT15: =1*(BT13=max($D$13:$CQ$13)) -> 0 | BU15: =1*(BU13=max($D$13:$CQ$13)) -> 0 | BV15: =1*(BV13=max($D$13:$CQ$13)) -> 0 | BW15: =1*(BW13=max($D$13:$CQ$13)) -> 0 | BX15: =1*(BX13=max($D$13:$CQ$13)) -> 1 | BY15: =1*(BY13=max($D$13:$CQ$13)) -> 0 | BZ15: =1*(BZ13=max($D$13:$CQ$13)) -> 0 | ... CX15: =1*(CX13=max($D$13:$CQ$13)) -> 0 | CY15: =1*(CY13=max($D$13:$CY$13)) -> 0
A16: Thiết bị giá tốt nhất đáp ứng | C16: =C15*(C14=minifs($D$14:$CY$14,$D$15:$CY$15,1)) -> 1 | D16: =D15*(D14=minifs($D$14:$CY$14,$D$15:$CY$15,1)) -> 0 | E16: =E15*(E14=minifs($D$14:$CY$14,$D$15:$CY$15,1)) -> 0 | F16: =F15*(F14=minifs($D$14:$CY$14,$D$15:$CY$15,1)) -> 0 | G16: =G15*(G14=minifs($D$14:$CY$14,$D$15:$CY$15,1)) -> 0 | H16: =H15*(H14=minifs($D$14:$CY$14,$D$15:$CY$15,1)) -> 0 | I16: =I15*(I14=minifs($D$14:$CY$14,$D$15:$CY$15,1)) -> 0 | J16: =J15*(J14=minifs($D$14:$CY$14,$D$15:$CY$15,1)) -> 0 | ... BR16: =BR15*(BR14=minifs($D$14:$CY$14,$D$15:$CY$15,1)) -> 0 | BS16: =BS15*(BS14=minifs($D$14:$CQ$14,$D$15:$CQ$15,1)) -> 0 | BT16: =BT15*(BT14=minifs($D$14:$CQ$14,$D$15:$CQ$15,1)) -> 0 | BU16: =BU15*(BU14=minifs($D$14:$CQ$14,$D$15:$CQ$15,1)) -> 0 | BV16: =BV15*(BV14=minifs($D$14:$CQ$14,$D$15:$CQ$15,1)) -> 0 | BW16: =BW15*(BW14=minifs($D$14:$CQ$14,$D$15:$CQ$15,1)) -> 0 | BX16: =BX15*(BX14=minifs($D$14:$CQ$14,$D$15:$CQ$15,1)) -> 1 | BY16: =BY15*(BY14=minifs($D$14:$CQ$14,$D$15:$CQ$15,1)) -> 0 | BZ16: =BZ15*(BZ14=minifs($D$14:$CQ$14,$D$15:$CQ$15,1)) -> 0 | ... CX16: =CX15*(CX14=minifs($D$14:$CQ$14,$D$15:$CQ$15,1)) -> 0 | CY16: =CY15*(CY14=minifs($D$14:$CY$14,$D$15:$CY$15,1)) -> 0
A17: Thiết bị khác đáp ứng | C17: =(1-($C$1=C1))*(C15=1) -> 0 | D17: =(1-($C$1=D1))*(D15=1) -> 0 | E17: =(1-($C$1=E1))*(E15=1) -> 0 | F17: =(1-($C$1=F1))*(F15=1) -> 0 | G17: =(1-($C$1=G1))*(G15=1) -> 0 | H17: =(1-($C$1=H1))*(H15=1) -> 0 | I17: =(1-($C$1=I1))*(I15=1) -> 0 | J17: =(1-($C$1=J1))*(J15=1) -> 0 | ... CY17: =(1-($C$1=CY1))*(CY15=1) -> 0
A19: Các lựa chọn khác | C19: =IFERROR(__xludf.DUMMYFUNCTION("iferror(filter(D1:CY1,$D$17:$CY$17=1),"""")"),"C9500X-60L4D") -> C9500X-60L4D
A20: =A2 -> Switching Bandwidth - Full Duplex (Gbps) | B20: =B2 | C20: =IFERROR(__xludf.DUMMYFUNCTION("iferror(filter(D2:CY2,$D$17:$CY$17=1),"""")"),9200.0) -> 9200
A21: =A3 -> Forwarding Capacity (Mpps) | B21: =B3 | C21: =IFERROR(__xludf.DUMMYFUNCTION("iferror(filter(D3:CY3,$D$17:$CY$17=1),"""")"),8000.0) -> 8000
A22: =A4 -> Số lượng cổng 1GE đồng | B22: =B4 | C22: =IFERROR(__xludf.DUMMYFUNCTION("iferror(filter(D4:CY4,$D$17:$CY$17=1),"""")"),"")
A23: =A5 -> Số lượng cổng 1GE SFP | B23: =B5 | C23: =IFERROR(__xludf.DUMMYFUNCTION("iferror(filter(D5:CY5,$D$17:$CY$17=1),"""")"),"")
A24: =A6 -> Số lượng cổng 10GE đồng | B24: =B6 | C24: =IFERROR(__xludf.DUMMYFUNCTION("iferror(filter(D6:CY6,$D$17:$CY$17=1),"""")"),"")
A25: =A7 -> Số lượng cổng 10GE quang | B25: =B7 -> 48 | C25: =IFERROR(__xludf.DUMMYFUNCTION("iferror(filter(D7:CY7,$D$17:$CY$17=1),"""")"),60.0) -> 60
A26: =A8 -> Số lượng cổng 100GE | B26: =B8 | C26: =IFERROR(__xludf.DUMMYFUNCTION("iferror(filter(D8:CY8,$D$17:$CY$17=1),"""")"),4.0) -> 4
A27: =A9 -> Stacking (Y/N) | B27: =B9 | C27: =IFERROR(__xludf.DUMMYFUNCTION("iferror(filter(D9:CY9,$D$17:$CY$17=1),"""")"),"Y") -> Y
A28: =A10 -> PoE (Y/N) | C28: =IFERROR(__xludf.DUMMYFUNCTION("iferror(filter(D10:AQ10,$D$17:$AQ$17=1),"""")"),"")

Sheet NexusSwitch
A1: Nexus Switch | B1: Requirement | C1: {=INDEX(D1:Q1, MATCH(1, D16:Q16, 0))} -> N9K-C93180YC-FX3 | D1: N9K-C9504 | E1: N9K-C9508 | F1: N9K-C9516 | G1: N9K-C9348GC-FX3 | H1: N9K-C93108TC-FX3 | I1: N9K-C93216TC-FX2 | J1: N9K-C93360YC-FX2 | K1: N9K-C93240YC-FX2 | L1: N9K-C93180YC-FX3 | M1: N9K-C93600CD-GX | N1: N9K-C9316D-GX | O1: N9K-C9364C-GX | P1: N9K-X9736C-FX3=
A2: =Specs!C2 -> Switching Bandwidth - Full Duplex (Gbps) | B2: =IFERROR(__xludf.DUMMYFUNCTION("IMPORTRANGE(""https://docs.google.com/spreadsheets/d/18TjePryHG687L54fIGU6Od12DGyT3mPoblPemZTZRY4"",""SwitchCampus!B3:B10"")"),"") | C2: =hlookup($C$1,$D$1:$Q$10,2,0)
A3: =Specs!C3 -> Forwarding Capacity (Mpps) | C3: =hlookup($C$1,$D$1:$Q$10,3,0)
A4: =Specs!C4 -> Số lượng cổng 1GE đồng | C4: =hlookup($C$1,$D$1:$Q$10,4,0) | G4: 48 | H4: 48 | I4: 96
A5: =Specs!C5 -> Số lượng cổng 1GE SFP | C5: =hlookup($C$1,$D$1:$Q$10,5,0) -> 48 | J5: 96 | K5: 48 | L5: 48
A6: =Specs!C6 -> Số lượng cổng 10GE đồng | C6: =hlookup($C$1,$D$1:$Q$10,6,0) | H6: 48 | I6: 96
A7: =Specs!C7 -> Số lượng cổng 10GE quang | B7: =IFERROR(__xludf.DUMMYFUNCTION("""COMPUTED_VALUE"""),48.0) -> 48 | C7: =hlookup($C$1,$D$1:$Q$10,7,0) -> 48 | G7: 4 | J7: 96 | K7: 48 | L7: 48
A8: =Specs!C8 -> Số lượng cổng 100GE | C8: =hlookup($C$1,$D$1:$Q$10,8,0) -> 6 | D8: 144 | E8: 288 | F8: 576 | G8: 2 | H8: 6 | I8: 12 | J8: 12 | K8: 12 | L8: 6 | M8: 36 | N8: 16 | O8: 64 | P8: 36
A9: =Specs!C9 -> Stacking (Y/N) | C9: =hlookup($C$1,$D$1:$Q$10,9,0)
A10: =Specs!C10 -> PoE (Y/N) | C10: =hlookup($C$1,$D$1:$Q$10,10,0)
A11: Switch Class | C11: =hlookup($C$1,$D$1:$Q$11,11,0) -> High End | D11: High End | E11: High End | F11: High End | G11: High End | H11: High End | I11: High End | J11: High End | K11: High End | L11: High End | M11: High End | N11: High End | O11: High End | P11: High End
A13: Số tiêu chí đáp ứng | C13: =sum(1*(C2>=$B$2)+1*(C3>=$B$3)+1*(C4>=$B$4)+1*(C5>=$B$5)+1*(C6>=$B$6)+1*(C7>=$B$7)+1*(C8>=$B$8)+1*or(C9="Y",$B$9="N",$B$9="")+1*or(C10="Y",$B$10="N",$B$10="")) -> 9 | D13: =sum(1*(D2>=$B$2)+1*(D3>=$B$3)+1*(D4>=$B$4)+1*(D5>=$B$5)+1*(D6>=$B$6)+1*(D7>=$B$7)+1*(D8>=$B$8)+1*or(D9="Y",$B$9="N",$B$9="")+1*or(D10="Y",$B$10="N",$B$10="")) -> 8 | E13: =sum(1*(E2>=$B$2)+1*(E3>=$B$3)+1*(E4>=$B$4)+1*(E5>=$B$5)+1*(E6>=$B$6)+1*(E7>=$B$7)+1*(E8>=$B$8)+1*or(E9="Y",$B$9="N",$B$9="")+1*or(E10="Y",$B$10="N",$B$10="")) -> 8 | F13: =sum(1*(F2>=$B$2)+1*(F3>=$B$3)+1*(F4>=$B$4)+1*(F5>=$B$5)+1*(F6>=$B$6)+1*(F7>=$B$7)+1*(F8>=$B$8)+1*or(F9="Y",$B$9="N",$B$9="")+1*or(F10="Y",$B$10="N",$B$10="")) -> 8 | G13: =sum(1*(G2>=$B$2)+1*(G3>=$B$3)+1*(G4>=$B$4)+1*(G5>=$B$5)+1*(G6>=$B$6)+1*(G7>=$B$7)+1*(G8>=$B$8)+1*or(G9="Y",$B$9="N",$B$9="")+1*or(G10="Y",$B$10="N",$B$10="")) -> 8 | H13: =sum(1*(H2>=$B$2)+1*(H3>=$B$3)+1*(H4>=$B$4)+1*(H5>=$B$5)+1*(H6>=$B$6)+1*(H7>=$B$7)+1*(H8>=$B$8)+1*or(H9="Y",$B$9="N",$B$9="")+1*or(H10="Y",$B$10="N",$B$10="")) -> 8 | I13: =sum(1*(I2>=$B$2)+1*(I3>=$B$3)+1*(I4>=$B$4)+1*(I5>=$B$5)+1*(I6>=$B$6)+1*(I7>=$B$7)+1*(I8>=$B$8)+1*or(I9="Y",$B$9="N",$B$9="")+1*or(I10="Y",$B$10="N",$B$10="")) -> 8 | J13: =sum(1*(J2>=$B$2)+1*(J3>=$B$3)+1*(J4>=$B$4)+1*(J5>=$B$5)+1*(J6>=$B$6)+1*(J7>=$B$7)+1*(J8>=$B$8)+1*or(J9="Y",$B$9="N",$B$9="")+1*or(J10="Y",$B$10="N",$B$10="")) -> 9 | ... Q13: =sum(1*(Q2>=$B$2)+1*(Q3>=$B$3)+1*(Q4>=$B$4)+1*(Q5>=$B$5)+1*(Q6>=$B$6)+1*(Q7>=$B$7)+1*(Q8>=$B$8)+1*or(Q9="Y",$B$9="N",$B$9="")+1*or(Q10="Y",$B$10="N",$B$10="")) -> 8
A14: Giá dự toán | C14: =iferror(vlookup(C1,AllListPrice!$A$2:$D$1000,4,0),0) -> 73302.82 | D14: =iferror(vlookup(D1,AllListPrice!$A$2:$D$1000,4,0),0) -> 383674.39 | E14: =iferror(vlookup(E1,AllListPrice!$A$2:$D$1000,4,0),0) -> 645324.61 | F14: =iferror(vlookup(F1,AllListPrice!$A$2:$D$1000,4,0),0) -> 761874.61 | G14: =iferror(vlookup(G1,AllListPrice!$A$2:$D$1000,4,0),0) -> 32577.06 | H14: =iferror(vlookup(H1,AllListPrice!$A$2:$D$1000,4,0),0) -> 78416.27 | I14: =iferror(vlookup(I1,AllListPrice!$A$2:$D$1000,4,0),0) -> 95212.19 | J14: =iferror(vlookup(J1,AllListPrice!$A$2:$D$1000,4,0),0) -> 95456.27 | ... P14: =iferror(vlookup(P1,AllListPrice!$A$2:$D$1000,4,0),0) -> 59012.02 | Q14: =iferror(vlookup(Q1,Cisco!$A$2:$D$1000,4,0),0) -> 0
A15: Thiết bị đáp ứng sát nhất số lượng tiêu chí YCKT | C15: =1*(C13=max($D$13:$Q$13)) -> 1 | D15: =1*(D13=max($D$13:$Q$13)) -> 0 | E15: =1*(E13=max($D$13:$Q$13)) -> 0 | F15: =1*(F13=max($D$13:$Q$13)) -> 0 | G15: =1*(G13=max($D$13:$Q$13)) -> 0 | H15: =1*(H13=max($D$13:$Q$13)) -> 0 | I15: =1*(I13=max($D$13:$Q$13)) -> 0 | J15: =1*(J13=max($D$13:$Q$13)) -> 1 | ... Q15: =1*(Q13=max($D$13:$Q$13)) -> 0
A16: Thiết bị giá tốt nhất đáp ứng | C16: =C15*(C14=minifs($D$14:$Q$14,$D$15:$Q$15,1)) -> 1 | D16: =D15*(D14=minifs($D$14:$Q$14,$D$15:$Q$15,1)) -> 0 | E16: =E15*(E14=minifs($D$14:$Q$14,$D$15:$Q$15,1)) -> 0 | F16: =F15*(F14=minifs($D$14:$Q$14,$D$15:$Q$15,1)) -> 0 | G16: =G15*(G14=minifs($D$14:$Q$14,$D$15:$Q$15,1)) -> 0 | H16: =H15*(H14=minifs($D$14:$Q$14,$D$15:$Q$15,1)) -> 0 | I16: =I15*(I14=minifs($D$14:$Q$14,$D$15:$Q$15,1)) -> 0 | J16: =J15*(J14=minifs($D$14:$Q$14,$D$15:$Q$15,1)) -> 0 | ... Q16: =Q15*(Q14=minifs($D$14:$Q$14,$D$15:$Q$15,1)) -> 0
A17: Thiết bị khác đáp ứng | C17: =(1-($C$1=C1))*(C15=1) -> 0 | D17: =(1-($C$1=D1))*(D15=1) -> 0 | E17: =(1-($C$1=E1))*(E15=1) -> 0 | F17: =(1-($C$1=F1))*(F15=1) -> 0 | G17: =(1-($C$1=G1))*(G15=1) -> 0 | H17: =(1-($C$1=H1))*(H15=1) -> 0 | I17: =(1-($C$1=I1))*(I15=1) -> 0 | J17: =(1-($C$1=J1))*(J15=1) -> 1 | ... Q17: =(1-($C$1=Q1))*(Q15=1) -> 0
A19: Các lựa chọn khác | C19: =IFERROR(__xludf.DUMMYFUNCTION("iferror(filter(D1:Q1,$D$17:$Q$17=1),"""")"),"N9K-C93360YC-FX2") -> N9K-C93360YC-FX2 | D19: =IFERROR(__xludf.DUMMYFUNCTION("""COMPUTED_VALUE"""),"N9K-C93240YC-FX2") -> N9K-C93240YC-FX2
A20: =A2 -> Switching Bandwidth - Full Duplex (Gbps) | B20: =B2 | C20: =IFERROR(__xludf.DUMMYFUNCTION("iferror(filter(D2:Q2,$D$17:$Q$17=1),"""")"),"")
A21: =A3 -> Forwarding Capacity (Mpps) | B21: =B3 | C21: =IFERROR(__xludf.DUMMYFUNCTION("iferror(filter(D3:Q3,$D$17:$Q$17=1),"""")"),"")
A22: =A4 -> Số lượng cổng 1GE đồng | B22: =B4 | C22: =IFERROR(__xludf.DUMMYFUNCTION("iferror(filter(D4:Q4,$D$17:$Q$17=1),"""")"),"")
A23: =A5 -> Số lượng cổng 1GE SFP | B23: =B5 | C23: =IFERROR(__xludf.DUMMYFUNCTION("iferror(filter(D5:Q5,$D$17:$Q$17=1),"""")"),96.0) -> 96 | D23: =IFERROR(__xludf.DUMMYFUNCTION("""COMPUTED_VALUE"""),48.0) -> 48
A24: =A6 -> Số lượng cổng 10GE đồng | B24: =B6 | C24: =IFERROR(__xludf.DUMMYFUNCTION("iferror(filter(D6:Q6,$D$17:$Q$17=1),"""")"),"")
A25: =A7 -> Số lượng cổng 10GE quang | B25: =B7 -> 48 | C25: =IFERROR(__xludf.DUMMYFUNCTION("iferror(filter(D7:Q7,$D$17:$Q$17=1),"""")"),96.0) -> 96 | D25: =IFERROR(__xludf.DUMMYFUNCTION("""COMPUTED_VALUE"""),48.0) -> 48
A26: =A8 -> Số lượng cổng 100GE | B26: =B8 | C26: =IFERROR(__xludf.DUMMYFUNCTION("iferror(filter(D8:Q8,$D$17:$Q$17=1),"""")"),12.0) -> 12 | D26: =IFERROR(__xludf.DUMMYFUNCTION("""COMPUTED_VALUE"""),12.0) -> 12
A27: =A9 -> Stacking (Y/N) | B27: =B9 | C27: =IFERROR(__xludf.DUMMYFUNCTION("iferror(filter(D9:Q9,$D$17:$Q$17=1),"""")"),"")
A28: =A10 -> PoE (Y/N) | C28: =IFERROR(__xludf.DUMMYFUNCTION("iferror(filter(#REF!,#REF!=1),"""")"),"")

Sheet ModularSwitch
A1: =Specs!D1 -> ModularSwitch | B1: Requirement | C1: {=INDEX(D1:Q1, MATCH(1, D16:Q16, 0))} -> C9600-LC-48YL= | D1: C9404R | E1: C9407R | F1: C9410R | G1: C9606R | H1: C9400-LC-12QC= | I1: C9400-LC-48T= | J1: C9400-LC-48TX= | K1: C9400-LC-48S= | L1: C9400-LC-48XS= | M1: C9600-LC-48TX= | N1: C9600-LC-48YL= | O1: C9600-LC-40YL4CD= | P1: C9600-LC-24C=
A2: =Specs!D2 -> Switching Bandwidth - Full Duplex (Gbps) | B2: =IFERROR(__xludf.DUMMYFUNCTION("IMPORTRANGE(""https://docs.google.com/spreadsheets/d/18TjePryHG687L54fIGU6Od12DGyT3mPoblPemZTZRY4"",""SwitchCampus!B3:B10"")"),"") | C2: =hlookup($C$1,$D$1:$Q$10,2,0) | D2: =480*2 -> 960 | E2: =480*5 -> 2400 | F2: =480*8 -> 3840 | G2: =3200*4 -> 12800
A3: =Specs!D3 -> Forwarding Capacity (Mpps) | C3: =hlookup($C$1,$D$1:$Q$10,3,0)
A4: =Specs!D4 -> Số lượng cổng 1GE đồng | C4: =hlookup($C$1,$D$1:$Q$10,4,0) | D4: 96 | E4: 240 | F4: 384 | G4: 192 | I4: 48 | J4: 48 | M4: 48
A5: =Specs!D5 -> Số lượng cổng 1GE SFP | C5: =hlookup($C$1,$D$1:$Q$10,5,0) -> 48 | D5: 96 | E5: 240 | F5: 384 | G5: 192 | K5: 48 | L5: 48 | N5: 48 | O5: 40
A6: =Specs!D6 -> Số lượng cổng 10GE đồng | C6: =hlookup($C$1,$D$1:$Q$10,6,0) | D6: 96 | E6: 240 | F6: 384 | G6: 192 | J6: 48 | M6: 48
A7: =Specs!D7 -> Số lượng cổng 10GE quang | B7: =IFERROR(__xludf.DUMMYFUNCTION("""COMPUTED_VALUE"""),48.0) -> 48 | C7: =hlookup($C$1,$D$1:$Q$10,7,0) -> 48 | D7: 96 | E7: 240 | F7: 384 | G7: 224 | L7: 48 | N7: 48 | O7: 40
A8: =Specs!D8 -> Số lượng cổng 100GE | C8: =hlookup($C$1,$D$1:$Q$10,8,0) | D8: 8 | E8: 20 | F8: 32 | G8: 128 | H8: 12 | O8: 4 | P8: 12
A9: =Specs!D9 -> Stacking (Y/N) | C9: =hlookup($C$1,$D$1:$Q$10,9,0) | D9: Y | E9: Y | F9: Y | G9: Y
A10: =Specs!D10 -> PoE (Y/N) | C10: =hlookup($C$1,$D$1:$Q$10,10,0) | D10: Y | E10: Y | F10: Y | G10: N
A11: Switch Class | C11: =hlookup($C$1,$D$1:$Q$11,11,0) | D11: High End | E11: High End | F11: High End | G11: High End
A13: Số tiêu chí đáp ứng | C13: =sum(1*(C2>=$B$2)+1*(C3>=$B$3)+1*(C4>=$B$4)+1*(C5>=$B$5)+1*(C6>=$B$6)+1*(C7>=$B$7)+1*(C8>=$B$8)+1*or(C9="Y",$B$9="N",$B$9="")+1*or(C10="Y",$B$10="N",$B$10="")) -> 9 | D13: =sum(1*(D2>=$B$2)+1*(D3>=$B$3)+1*(D4>=$B$4)+1*(D5>=$B$5)+1*(D6>=$B$6)+1*(D7>=$B$7)+1*(D8>=$B$8)+1*or(D9="Y",$B$9="N",$B$9="")+1*or(D10="Y",$B$10="N",$B$10="")) -> 9 | E13: =sum(1*(E2>=$B$2)+1*(E3>=$B$3)+1*(E4>=$B$4)+1*(E5>=$B$5)+1*(E6>=$B$6)+1*(E7>=$B$7)+1*(E8>=$B$8)+1*or(E9="Y",$B$9="N",$B$9="")+1*or(E10="Y",$B$10="N",$B$10="")) -> 9 | F13: =sum(1*(F2>=$B$2)+1*(F3>=$B$3)+1*(F4>=$B$4)+1*(F5>=$B$5)+1*(F6>=$B$6)+1*(F7>=$B$7)+1*(F8>=$B$8)+1*or(F9="Y",$B$9="N",$B$9="")+1*or(F10="Y",$B$10="N",$B$10="")) -> 9 | G13: =sum(1*(G2>=$B$2)+1*(G3>=$B$3)+1*(G4>=$B$4)+1*(G5>=$B$5)+1*(G6>=$B$6)+1*(G7>=$B$7)+1*(G8>=$B$8)+1*or(G9="Y",$B$9="N",$B$9="")+1*or(G10="Y",$B$10="N",$B$10="")) -> 9 | H13: =sum(1*(H2>=$B$2)+1*(H3>=$B$3)+1*(H4>=$B$4)+1*(H5>=$B$5)+1*(H6>=$B$6)+1*(H7>=$B$7)+1*(H8>=$B$8)+1*or(H9="Y",$B$9="N",$B$9="")+1*or(H10="Y",$B$10="N",$B$10="")) -> 8 | I13: =sum(1*(I2>=$B$2)+1*(I3>=$B$3)+1*(I4>=$B$4)+1*(I5>=$B$5)+1*(I6>=$B$6)+1*(I7>=$B$7)+1*(I8>=$B$8)+1*or(I9="Y",$B$9="N",$B$9="")+1*or(I10="Y",$B$10="N",$B$10="")) -> 8 | J13: =sum(1*(J2>=$B$2)+1*(J3>=$B$3)+1*(J4>=$B$4)+1*(J5>=$B$5)+1*(J6>=$B$6)+1*(J7>=$B$7)+1*(J8>=$B$8)+1*or(J9="Y",$B$9="N",$B$9="")+1*or(J10="Y",$B$10="N",$B$10="")) -> 8 | ... Q13: =sum(1*(Q2>=$B$2)+1*(Q3>=$B$3)+1*(Q4>=$B$4)+1*(Q5>=$B$5)+1*(Q6>=$B$6)+1*(Q7>=$B$7)+1*(Q8>=$B$8)+1*or(Q9="Y",$B$9="N",$B$9="")+1*or(Q10="Y",$B$10="N",$B$10="")) -> 8
A14: Giá dự toán | C14: =iferror(vlookup(C1,AllListPrice!$A$2:$D$1000,4,0),0) -> 28916.35 | D14: =iferror(vlookup(D1,AllListPrice!$A$2:$D$1000,4,0),0) -> 117530.33 | E14: =iferror(vlookup(E1,AllListPrice!$A$2:$D$1000,4,0),0) -> 136174.7 | F14: =iferror(vlookup(F1,AllListPrice!$A$2:$D$1000,4,0),0) -> 144810.28 | G14: =iferror(vlookup(G1,AllListPrice!$A$2:$D$1000,4,0),0) -> 246495.41 | H14: =iferror(vlookup(H1,AllListPrice!$A$2:$D$1000,4,0),0) -> 38258 | I14: =iferror(vlookup(I1,AllListPrice!$A$2:$D$1000,4,0),0) -> 8689.51 | J14: =iferror(vlookup(J1,AllListPrice!$A$2:$D$1000,4,0),0) -> 19129 | ... P14: =iferror(vlookup(P1,AllListPrice!$A$2:$D$1000,4,0),0) -> 32859.49 | Q14: =iferror(vlookup(Q1,Cisco!$A$2:$D$1000,4,0),0) -> 0
A15: Thiết bị đáp ứng sát nhất số lượng tiêu chí YCKT | C15: =1*(C13=max($D$13:$Q$13)) -> 1 | D15: =1*(D13=max($D$13:$Q$13)) -> 1 | E15: =1*(E13=max($D$13:$Q$13)) -> 1 | F15: =1*(F13=max($D$13:$Q$13)) -> 1 | G15: =1*(G13=max($D$13:$Q$13)) -> 1 | H15: =1*(H13=max($D$13:$Q$13)) -> 0 | I15: =1*(I13=max($D$13:$Q$13)) -> 0 | J15: =1*(J13=max($D$13:$Q$13)) -> 0 | ... Q15: =1*(Q13=max($D$13:$Q$13)) -> 0
A16: Thiết bị giá tốt nhất đáp ứng | C16: =C15*(C14=minifs($D$14:$Q$14,$D$15:$Q$15,1)) -> 1 | D16: =D15*(D14=minifs($D$14:$Q$14,$D$15:$Q$15,1)) -> 0 | E16: =E15*(E14=minifs($D$14:$Q$14,$D$15:$Q$15,1)) -> 0 | F16: =F15*(F14=minifs($D$14:$Q$14,$D$15:$Q$15,1)) -> 0 | G16: =G15*(G14=minifs($D$14:$Q$14,$D$15:$Q$15,1)) -> 0 | H16: =H15*(H14=minifs($D$14:$Q$14,$D$15:$Q$15,1)) -> 0 | I16: =I15*(I14=minifs($D$14:$Q$14,$D$15:$Q$15,1)) -> 0 | J16: =J15*(J14=minifs($D$14:$Q$14,$D$15:$Q$15,1)) -> 0 | ... Q16: =Q15*(Q14=minifs($D$14:$Q$14,$D$15:$Q$15,1)) -> 0
A17: Thiết bị khác đáp ứng | C17: =(1-($C$1=C1))*(C15=1) -> 0 | D17: =(1-($C$1=D1))*(D15=1) -> 1 | E17: =(1-($C$1=E1))*(E15=1) -> 1 | F17: =(1-($C$1=F1))*(F15=1) -> 1 | G17: =(1-($C$1=G1))*(G15=1) -> 1 | H17: =(1-($C$1=H1))*(H15=1) -> 0 | I17: =(1-($C$1=I1))*(I15=1) -> 0 | J17: =(1-($C$1=J1))*(J15=1) -> 0 | ... Q17: =(1-($C$1=Q1))*(Q15=1) -> 0
A19: Các lựa chọn khác | C19: =IFERROR(__xludf.DUMMYFUNCTION("iferror(filter(D1:Q1,$D$17:$Q$17=1),"""")"),"C9404R") -> C9404R | D19: =IFERROR(__xludf.DUMMYFUNCTION("""COMPUTED_VALUE"""),"C9407R") -> C9407R | E19: =IFERROR(__xludf.DUMMYFUNCTION("""COMPUTED_VALUE"""),"C9410R") -> C9410R | F19: =IFERROR(__xludf.DUMMYFUNCTION("""COMPUTED_VALUE"""),"C9606R") -> C9606R | G19: =IFERROR(__xludf.DUMMYFUNCTION("""COMPUTED_VALUE"""),"C9400-LC-48XS=") -> C9400-LC-48XS=
A20: =A2 -> Switching Bandwidth - Full Duplex (Gbps) | B20: =B2 | C20: =IFERROR(__xludf.DUMMYFUNCTION("iferror(filter(D2:Q2,$D$17:$Q$17=1),"""")"),960.0) -> 960 | D20: =IFERROR(__xludf.DUMMYFUNCTION("""COMPUTED_VALUE"""),2400.0) -> 2400 | E20: =IFERROR(__xludf.DUMMYFUNCTION("""COMPUTED_VALUE"""),3840.0) -> 3840 | F20: =IFERROR(__xludf.DUMMYFUNCTION("""COMPUTED_VALUE"""),12800.0) -> 12800
A21: =A3 -> Forwarding Capacity (Mpps) | B21: =B3 | C21: =IFERROR(__xludf.DUMMYFUNCTION("iferror(filter(D3:Q3,$D$17:$Q$17=1),"""")"),"")
A22: =A4 -> Số lượng cổng 1GE đồng | B22: =B4 | C22: =IFERROR(__xludf.DUMMYFUNCTION("iferror(filter(D4:Q4,$D$17:$Q$17=1),"""")"),96.0) -> 96 | D22: =IFERROR(__xludf.DUMMYFUNCTION("""COMPUTED_VALUE"""),240.0) -> 240 | E22: =IFERROR(__xludf.DUMMYFUNCTION("""COMPUTED_VALUE"""),384.0) -> 384 | F22: =IFERROR(__xludf.DUMMYFUNCTION("""COMPUTED_VALUE"""),192.0) -> 192
A23: =A5 -> Số lượng cổng 1GE SFP | B23: =B5 | C23: =IFERROR(__xludf.DUMMYFUNCTION("iferror(filter(D5:Q5,$D$17:$Q$17=1),"""")"),96.0) -> 96 | D23: =IFERROR(__xludf.DUMMYFUNCTION("""COMPUTED_VALUE"""),240.0) -> 240 | E23: =IFERROR(__xludf.DUMMYFUNCTION("""COMPUTED_VALUE"""),384.0) -> 384 | F23: =IFERROR(__xludf.DUMMYFUNCTION("""COMPUTED_VALUE"""),192.0) -> 192 | G23: =IFERROR(__xludf.DUMMYFUNCTION("""COMPUTED_VALUE"""),48.0) -> 48
A24: =A6 -> Số lượng cổng 10GE đồng | B24: =B6 | C24: =IFERROR(__xludf.DUMMYFUNCTION("iferror(filter(D6:Q6,$D$17:$Q$17=1),"""")"),96.0) -> 96 | D24: =IFERROR(__xludf.DUMMYFUNCTION("""COMPUTED_VALUE"""),240.0) -> 240 | E24: =IFERROR(__xludf.DUMMYFUNCTION("""COMPUTED_VALUE"""),384.0) -> 384 | F24: =IFERROR(__xludf.DUMMYFUNCTION("""COMPUTED_VALUE"""),192.0) -> 192
A25: =A7 -> Số lượng cổng 10GE quang | B25: =B7 -> 48 | C25: =IFERROR(__xludf.DUMMYFUNCTION("iferror(filter(D7:Q7,$D$17:$Q$17=1),"""")"),96.0) -> 96 | D25: =IFERROR(__xludf.DUMMYFUNCTION("""COMPUTED_VALUE"""),240.0) -> 240 | E25: =IFERROR(__xludf.DUMMYFUNCTION("""COMPUTED_VALUE"""),384.0) -> 384 | F25: =IFERROR(__xludf.DUMMYFUNCTION("""COMPUTED_VALUE"""),224.0) -> 224 | G25: =IFERROR(__xludf.DUMMYFUNCTION("""COMPUTED_VALUE"""),48.0) -> 48
A26: =A8 -> Số lượng cổng 100GE | B26: =B8 | C26: =IFERROR(__xludf.DUMMYFUNCTION("iferror(filter(D8:Q8,$D$17:$Q$17=1),"""")"),8.0) -> 8 | D26: =IFERROR(__xludf.DUMMYFUNCTION("""COMPUTED_VALUE"""),20.0) -> 20 | E26: =IFERROR(__xludf.DUMMYFUNCTION("""COMPUTED_VALUE"""),32.0) -> 32 | F26: =IFERROR(__xludf.DUMMYFUNCTION("""COMPUTED_VALUE"""),128.0) -> 128
A27: =A9 -> Stacking (Y/N) | B27: =B9 | C27: =IFERROR(__xludf.DUMMYFUNCTION("iferror(filter(D9:Q9,$D$17:$Q$17=1),"""")"),"Y") -> Y | D27: =IFERROR(__xludf.DUMMYFUNCTION("""COMPUTED_VALUE"""),"Y") -> Y | E27: =IFERROR(__xludf.DUMMYFUNCTION("""COMPUTED_VALUE"""),"Y") -> Y | F27: =IFERROR(__xludf.DUMMYFUNCTION("""COMPUTED_VALUE"""),"Y") -> Y
A28: =A10 -> PoE (Y/N) | C28: =IFERROR(__xludf.DUMMYFUNCTION("iferror(filter(D10:G10,$D$17:$G$17=1),"""")"),"Y") -> Y | D28: =IFERROR(__xludf.DUMMYFUNCTION("""COMPUTED_VALUE"""),"Y") -> Y | E28: =IFERROR(__xludf.DUMMYFUNCTION("""COMPUTED_VALUE"""),"Y") -> Y | F28: =IFERROR(__xludf.DUMMYFUNCTION("""COMPUTED_VALUE"""),"N") -> N

Sheet WiFi
A1: =Specs!E1 -> Wireless | B1: C9136I | C1: CW9162I | D1: CW9164I | E1: CW9166I | F1: CW9166D1 | G1: CW9172I | H1: CW9172H | I1: CW9176I | J1: CW9176D1 | K1: CW9178I | L1: C9124AXI | M1: C9124AXD | N1: C9124AXE | O1: CW9163E | Q1: AIR-PWRINJ7= | R1: IW-PWRINJ-60RGDMG=
A2: =Specs!E2 -> Loại Access Point (indoor/outdoor) | B2: indoor | C2: indoor | D2: indoor | E2: indoor | F2: indoor | G2: indoor | H2: indoor | I2: indoor | J2: indoor | K2: indoor | L2: outdoor | M2: outdoor | N2: outdoor | O2: outdoor
A3: =Specs!E3 -> Công nghệ WiFi (WiFi6/WiFi7) | B3: WiFi6E | C3: WiFi6E | D3: WiFi6E | E3: WiFi6E | F3: WiFi6E | G3: WiFi7 | H3: WiFi7 | I3: WiFi7 | J3: WiFi7 | K3: WiFi7 | L3: WiFi6 | M3: WiFi6 | N3: WiFi6 | O3: WiFi6E
A4: =Specs!E4 -> Số lượng người dùng trong phạm vi phủ sóng 1 AP | B4: 400 | C4: 400 | D4: 400 | E4: 400 | F4: 400 | G4: 256 | H4: 256 | I4: 400 | J4: 400 | K4: 400
A5: =Specs!E5 -> Bán kính phủ sóng (m) | B5: =roundup(1000*POWER(10,(((B18+B19-0-(-75)-30)-32.44-20*LOG10(6000))/20)),0) -> 20 | C5: =roundup(1000*POWER(10,(((C18+C19-0-(-75)-30)-32.44-20*LOG10(6000))/20)),0) -> 13 | D5: =roundup(1000*POWER(10,(((D18+D19-0-(-75)-30)-32.44-20*LOG10(6000))/20)),0) -> 16 | E5: =roundup(1000*POWER(10,(((E18+E19-0-(-75)-30)-32.44-20*LOG10(6000))/20)),0) -> 16 | F5: =roundup(1000*POWER(10,(((F18+F19-0-(-75)-30)-32.44-20*LOG10(6000))/20)),0) -> 26 | G5: =roundup(1000*POWER(10,(((G18+G19-0-(-75)-30)-32.44-20*LOG10(6000))/20)),0) -> 20 | H5: =roundup(1000*POWER(10,(((H18+H19-0-(-75)-30)-32.44-20*LOG10(6000))/20)),0) -> 20 | I5: =roundup(1000*POWER(10,(((I18+I19-0-(-75)-30)-32.44-20*LOG10(6000))/20)),0) -> 20 | ... O5: =roundup(1000*POWER(10,(((O18+O19-0-(-75)-30)-32.44-20*LOG10(6000))/20)),0) -> 26
A6: Công suất phát (dBm)
A7: Số lượng cổng Uplink 1GE RJ45 | B7: 2 | C7: 1 | D7: 1 | E7: 1 | F7: 1 | G7: 1 | H7: 1 | I7: 1 | J7: 1 | K7: 2 | L7: 1 | M7: 1 | N7: 1 | O7: 1
A8: Số lượng cổng Uplink 10GE RJ45 | I8: 1 | J8: 1 | K8: 2
A9: Số lượng cổng Uplink 1GE SFP | L9: 1 | M9: 1 | N9: 1
A10: Antenna Type (Omni or Directional) | B10: Omni | C10: Omni | D10: Omni | E10: Omni | F10: Directional | G10: Omni | H10: Omni | I10: Omni | J10: Directional | K10: Omni | L10: Omni | M10: Directional | N10: Depend on Antenna | O10: Depend on Antenna
A11: Access Point Class | B11: =if(ISNUMBER(find("WiFi6",B3)),"Mid Range",if(ISNUMBER(find("WiFi7",B3)),"High End","")) -> Mid Range | C11: =if(ISNUMBER(find("WiFi6",C3)),"Mid Range",if(ISNUMBER(find("WiFi7",C3)),"High End","")) -> Mid Range | D11: =if(ISNUMBER(find("WiFi6",D3)),"Mid Range",if(ISNUMBER(find("WiFi7",D3)),"High End","")) -> Mid Range | E11: =if(ISNUMBER(find("WiFi6",E3)),"Mid Range",if(ISNUMBER(find("WiFi7",E3)),"High End","")) -> Mid Range | F11: =if(ISNUMBER(find("WiFi6",F3)),"Mid Range",if(ISNUMBER(find("WiFi7",F3)),"High End","")) -> Mid Range | G11: =if(ISNUMBER(find("WiFi6",G3)),"Mid Range",if(ISNUMBER(find("WiFi7",G3)),"High End","")) -> High End | H11: =if(ISNUMBER(find("WiFi6",H3)),"Mid Range",if(ISNUMBER(find("WiFi7",H3)),"High End","")) -> High End | I11: =if(ISNUMBER(find("WiFi6",I3)),"Mid Range",if(ISNUMBER(find("WiFi7",I3)),"High End","")) -> High End | ... P11: =if(ISNUMBER(find("WiFi6",P3)),"Mid Range",if(ISNUMBER(find("WiFi7",P3)),"High End","")) | AQ11: High End | AR11: High End | AS11: High End
A12: Giá dự toán | B12: =iferror(vlookup(B1,AllListPrice!$A$2:$D$1000,4,0),0) -> 4892.02 | C12: =iferror(vlookup(C1,AllListPrice!$A$2:$D$1000,4,0),0) -> 2476.36 | D12: =iferror(vlookup(D1,AllListPrice!$A$2:$D$1000,4,0),0) -> 3786.46 | E12: =iferror(vlookup(E1,AllListPrice!$A$2:$D$1000,4,0),0) -> 4201.05 | F12: =iferror(vlookup(F1,AllListPrice!$A$2:$D$1000,4,0),0) -> 4615.63 | G12: =iferror(vlookup(G1,AllListPrice!$A$2:$D$1000,4,0),0) -> 2643.68 | H12: =iferror(vlookup(H1,AllListPrice!$A$2:$D$1000,4,0),0) -> 2350.28 | I12: =iferror(vlookup(I1,AllListPrice!$A$2:$D$1000,4,0),0) -> 4414.06 | ... AP12: =iferror(vlookup(AP1,AllListPrice!$A$2:$D$1000,4,0),0) -> 0
A16: =A9 -> Số lượng cổng Uplink 1GE SFP
A17: =A10 -> Antenna Type (Omni or Directional)
A18: Available transmit power settings | B18: 23 | C18: 20 | D18: 23 | E18: 23 | F18: 23 | G18: 23 | H18: 23 | I18: 23 | J18: 23 | K18: 23 | L18: 30 | M18: 30 | N18: 30 | O18: 23
A19: Antenna gain (dBi) | B19: 6 | C19: 5 | D19: 4 | E19: 4 | F19: 8 | G19: 6 | H19: 6 | I19: 6 | J19: 8 | K19: 6 | L19: 7 | M19: 9 | N19: 13 | O19: 8

Sheet SFP
A1: =Specs!I1 -> SFP | B1: Ficer-1G-10km | C1: Ficer-1G-40km | D1: Ficer-1G-80km | E1: Ficer-10G-10km | F1: Ficer-10G-40km | G1: Ficer-10G-80km | H1: Ficer-100G-10km | I1: Ficer-100G-40km | J1: Ficer-100G-80km | K1: GLC-SX-MMD= | L1: GLC-LH-SMD= | M1: GLC-EX-SMD= | N1: GLC-ZX-SMD= | O1: SFP-10G-SR-S= | P1: SFP-10G-SR= | Q1: SFP-10G-LR-S= | R1: SFP-10G-LR= | S1: SFP-10G-ER-S= | T1: SFP-10G-ER= | U1: SFP-10G-ZR-S= | V1: SFP-10G-ZR= | W1: QSFP-100G-LR4-S | X1: QSFP-100G-LR-S= | Y1: QSFP-100G-ER4L-S= | Z1: QSFP-100G-ZR4-S=
A2: =Specs!I2 -> Tốc độ (1G/10G/100G) | B2: 1 | C2: 1 | D2: 1 | E2: 10 | F2: 10 | G2: 10 | H2: 100 | I2: 100 | J2: 100 | K2: 1 | L2: 1 | M2: 1 | N2: 1 | O2: 10 | P2: 10 | Q2: 10 | R2: 10 | S2: 10 | T2: 10 | U2: 10 | V2: 10 | W2: 100 | X2: 100 | Y2: 100 | Z2: 100
A3: =Specs!I3 -> Khoảng cách truyền (km) | B3: 10 | C3: 40 | D3: 80 | E3: 10 | F3: 40 | G3: 80 | H3: 10 | I3: 40 | J3: 80 | K3: 0.5 | L3: 10 | M3: 40 | N3: 70 | O3: 0.5 | P3: 0.5 | Q3: 10 | R3: 10 | S3: 40 | T3: 40 | U3: 80 | V3: 80 | W3: 10 | X3: 10 | Y3: 40 | Z3: 80
A4: SFP Class | B4: Low End | C4: Low End | D4: Low End | E4: Low End | F4: Low End | G4: Low End | H4: Low End | I4: Low End | J4: Low End | K4: High End | L4: High End | M4: High End | N4: High End | O4: High End | P4: High End | Q4: High End | R4: High End | S4: High End | T4: High End | U4: High End | V4: High End | W4: High End | X4: High End | Y4: High End | Z4: High End
A5: Giá dự toán | B5: =iferror(vlookup(B1,AllListPrice!$A$2:$D$1000,4,0),0) -> 9 | C5: =iferror(vlookup(C1,AllListPrice!$A$2:$D$1000,4,0),0) -> 21 | D5: =iferror(vlookup(D1,AllListPrice!$A$2:$D$1000,4,0),0) -> 35 | E5: =iferror(vlookup(E1,AllListPrice!$A$2:$D$1000,4,0),0) -> 32 | F5: =iferror(vlookup(F1,AllListPrice!$A$2:$D$1000,4,0),0) -> 150 | G5: =iferror(vlookup(G1,AllListPrice!$A$2:$D$1000,4,0),0) -> 290 | H5: =iferror(vlookup(H1,AllListPrice!$A$2:$D$1000,4,0),0) -> 500 | I5: =iferror(vlookup(I1,AllListPrice!$A$2:$D$1000,4,0),0) -> 800 | ... V5: =iferror(vlookup(V1,AllListPrice!$A$2:$D$1000,4,0),0) -> 19472.29 | W5: =iferror(vlookup("100GQSFP-LR4-4=",AllListPrice!$A$2:$D$1000,4,0)/4,0) -> 9127.635 | X5: =iferror(vlookup(X1,AllListPrice!$A$2:$D$1000,4,0),0) -> 4130.83 | Y5: =iferror(vlookup(Y1,AllListPrice!$A$2:$D$1000,4,0),0) -> 91270.27 | Z5: =iferror(vlookup(Z1,AllListPrice!$A$2:$D$1000,4,0),0) -> 36190

Sheet AllDevices
A1: All Devices | B1: Đã có giá List chưa ?
A2: =IFERROR(__xludf.DUMMYFUNCTION("transpose(HSTACK( FILTER(Router!D1:EA1, Router!D1:EA1<>""""), FILTER(SwitchCampus!D1:DO1, SwitchCampus!D1:DO1<>""""), FILTER(NexusSwitch!D1:CY1, NexusSwitch!D1:CY1<>""""), FILTER(ModularSwitch!D1:CX1, ModularSwitch!D1:CX1<>""""), FILTER(WiFi!D1:CO1, WiFi!"&"D1:CO1<>""""), FILTER(SFP!D1:CP1, SFP!D1:CP1<>"""") ))"),"C1161-8P") -> C1161-8P | B2: =if(A2<>"",countif(AllListPrice!A:A,A2),"") -> 1
A3: =IFERROR(__xludf.DUMMYFUNCTION("""COMPUTED_VALUE"""),"C1161X-8P") -> C1161X-8P | B3: =if(A3<>"",countif(AllListPrice!A:A,A3),"") -> 1
A4: =IFERROR(__xludf.DUMMYFUNCTION("""COMPUTED_VALUE"""),"C1131-8PWS") -> C1131-8PWS | B4: =if(A4<>"",countif(AllListPrice!A:A,A4),"") -> 1
A5: =IFERROR(__xludf.DUMMYFUNCTION("""COMPUTED_VALUE"""),"C1131X-8PWS") -> C1131X-8PWS | B5: =if(A5<>"",countif(AllListPrice!A:A,A5),"") -> 1
A6: =IFERROR(__xludf.DUMMYFUNCTION("""COMPUTED_VALUE"""),"C1121-4P") -> C1121-4P | B6: =if(A6<>"",countif(AllListPrice!A:A,A6),"") -> 1
A7: =IFERROR(__xludf.DUMMYFUNCTION("""COMPUTED_VALUE"""),"C1121-8P") -> C1121-8P | B7: =if(A7<>"",countif(AllListPrice!A:A,A7),"") -> 1
A8: =IFERROR(__xludf.DUMMYFUNCTION("""COMPUTED_VALUE"""),"C1127-8PLTEP") -> C1127-8PLTEP | B8: =if(A8<>"",countif(AllListPrice!A:A,A8),"") -> 1
A9: =IFERROR(__xludf.DUMMYFUNCTION("""COMPUTED_VALUE"""),"C1116-4P") -> C1116-4P | B9: =if(A9<>"",countif(AllListPrice!A:A,A9),"") -> 1
A10: =IFERROR(__xludf.DUMMYFUNCTION("""COMPUTED_VALUE"""),"C1117-4P") -> C1117-4P | B10: =if(A10<>"",countif(AllListPrice!A:A,A10),"") -> 1
A11: =IFERROR(__xludf.DUMMYFUNCTION("""COMPUTED_VALUE"""),"C1112-8P") -> C1112-8P | B11: =if(A11<>"",countif(AllListPrice!A:A,A11),"") -> 1
A12: =IFERROR(__xludf.DUMMYFUNCTION("""COMPUTED_VALUE"""),"C1109-4PLTE2P") -> C1109-4PLTE2P | B12: =if(A12<>"",countif(AllListPrice!A:A,A12),"") -> 1
A13: =IFERROR(__xludf.DUMMYFUNCTION("""COMPUTED_VALUE"""),"C8200L-1N-4T") -> C8200L-1N-4T | B13: =if(A13<>"",countif(AllListPrice!A:A,A13),"") -> 1
A14: =IFERROR(__xludf.DUMMYFUNCTION("""COMPUTED_VALUE"""),"C8200-1N-4T") -> C8200-1N-4T | B14: =if(A14<>"",countif(AllListPrice!A:A,A14),"") -> 1
A15: =IFERROR(__xludf.DUMMYFUNCTION("""COMPUTED_VALUE"""),"C8300-1N1S-6T") -> C8300-1N1S-6T | B15: =if(A15<>"",countif(AllListPrice!A:A,A15),"") -> 1
A16: =IFERROR(__xludf.DUMMYFUNCTION("""COMPUTED_VALUE"""),"C8300-2N2S-6T") -> C8300-2N2S-6T | B16: =if(A16<>"",countif(AllListPrice!A:A,A16),"") -> 1
A17: =IFERROR(__xludf.DUMMYFUNCTION("""COMPUTED_VALUE"""),"C8300-1N1S-4T2X") -> C8300-1N1S-4T2X | B17: =if(A17<>"",countif(AllListPrice!A:A,A17),"") -> 1
A18: =IFERROR(__xludf.DUMMYFUNCTION("""COMPUTED_VALUE"""),"C8300-2N2S-4T2X") -> C8300-2N2S-4T2X | B18: =if(A18<>"",countif(AllListPrice!A:A,A18),"") -> 1
A19: =IFERROR(__xludf.DUMMYFUNCTION("""COMPUTED_VALUE"""),"C8500L-8S4X") -> C8500L-8S4X | B19: =if(A19<>"",countif(AllListPrice!A:A,A19),"") -> 1
A20: =IFERROR(__xludf.DUMMYFUNCTION("""COMPUTED_VALUE"""),"C8500-12X") -> C8500-12X | B20: =if(A20<>"",countif(AllListPrice!A:A,A20),"") -> 1
A21: =IFERROR(__xludf.DUMMYFUNCTION("""COMPUTED_VALUE"""),"C8500-12X4QC") -> C8500-12X4QC | B21: =if(A21<>"",countif(AllListPrice!A:A,A21),"") -> 1
A22: =IFERROR(__xludf.DUMMYFUNCTION("""COMPUTED_VALUE"""),"C8500-20X6C") -> C8500-20X6C | B22: =if(A22<>"",countif(AllListPrice!A:A,A22),"") -> 1
A23: =IFERROR(__xludf.DUMMYFUNCTION("""COMPUTED_VALUE"""),"C1300-8T-E-2G") -> C1300-8T-E-2G | B23: =if(A23<>"",countif(AllListPrice!A:A,A23),"") -> 1
A24: =IFERROR(__xludf.DUMMYFUNCTION("""COMPUTED_VALUE"""),"C1300-8P-E-2G") -> C1300-8P-E-2G | B24: =if(A24<>"",countif(AllListPrice!A:A,A24),"") -> 1
A25: =IFERROR(__xludf.DUMMYFUNCTION("""COMPUTED_VALUE"""),"C1300-8FP-2G") -> C1300-8FP-2G | B25: =if(A25<>"",countif(AllListPrice!A:A,A25),"") -> 1
A26: =IFERROR(__xludf.DUMMYFUNCTION("""COMPUTED_VALUE"""),"C1300-16T-2G") -> C1300-16T-2G | B26: =if(A26<>"",countif(AllListPrice!A:A,A26),"") -> 1
A27: =IFERROR(__xludf.DUMMYFUNCTION("""COMPUTED_VALUE"""),"C1300-16P-2G") -> C1300-16P-2G | B27: =if(A27<>"",countif(AllListPrice!A:A,A27),"") -> 1
A28: =IFERROR(__xludf.DUMMYFUNCTION("""COMPUTED_VALUE"""),"C1300-16FP-2G") -> C1300-16FP-2G | B28: =if(A28<>"",countif(AllListPrice!A:A,A28),"") -> 1
A29: =IFERROR(__xludf.DUMMYFUNCTION("""COMPUTED_VALUE"""),"C1300-24T-4G") -> C1300-24T-4G | B29: =if(A29<>"",countif(AllListPrice!A:A,A29),"") -> 1
A30: =IFERROR(__xludf.DUMMYFUNCTION("""COMPUTED_VALUE"""),"C1300-24P-4G") -> C1300-24P-4G | B30: =if(A30<>"",countif(AllListPrice!A:A,A30),"") -> 1
A31: =IFERROR(__xludf.DUMMYFUNCTION("""COMPUTED_VALUE"""),"C1300-24FP-4G") -> C1300-24FP-4G | B31: =if(A31<>"",countif(AllListPrice!A:A,A31),"") -> 1
A32: =IFERROR(__xludf.DUMMYFUNCTION("""COMPUTED_VALUE"""),"C1300-48T-4G") -> C1300-48T-4G | B32: =if(A32<>"",countif(AllListPrice!A:A,A32),"") -> 1
A33: =IFERROR(__xludf.DUMMYFUNCTION("""COMPUTED_VALUE"""),"C1300-48P-4G") -> C1300-48P-4G | B33: =if(A33<>"",countif(AllListPrice!A:A,A33),"") -> 1
A34: =IFERROR(__xludf.DUMMYFUNCTION("""COMPUTED_VALUE"""),"C1300-48FP-4G") -> C1300-48FP-4G | B34: =if(A34<>"",countif(AllListPrice!A:A,A34),"") -> 1
A35: =IFERROR(__xludf.DUMMYFUNCTION("""COMPUTED_VALUE"""),"C1300-16P-4X") -> C1300-16P-4X | B35: =if(A35<>"",countif(AllListPrice!A:A,A35),"") -> 1
A36: =IFERROR(__xludf.DUMMYFUNCTION("""COMPUTED_VALUE"""),"C1300-24T-4X") -> C1300-24T-4X | B36: =if(A36<>"",countif(AllListPrice!A:A,A36),"") -> 1
A37: =IFERROR(__xludf.DUMMYFUNCTION("""COMPUTED_VALUE"""),"C1300-24P-4X") -> C1300-24P-4X | B37: =if(A37<>"",countif(AllListPrice!A:A,A37),"") -> 1
A38: =IFERROR(__xludf.DUMMYFUNCTION("""COMPUTED_VALUE"""),"C1300-24FP-4X") -> C1300-24FP-4X | B38: =if(A38<>"",countif(AllListPrice!A:A,A38),"") -> 1
A39: =IFERROR(__xludf.DUMMYFUNCTION("""COMPUTED_VALUE"""),"C1300-48T-4X") -> C1300-48T-4X | B39: =if(A39<>"",countif(AllListPrice!A:A,A39),"") -> 1
A40: =IFERROR(__xludf.DUMMYFUNCTION("""COMPUTED_VALUE"""),"C1300-48P-4X") -> C1300-48P-4X | B40: =if(A40<>"",countif(AllListPrice!A:A,A40),"") -> 1
...

Sheet Cisco
A1: =IFERROR(__xludf.DUMMYFUNCTION("IMPORTRANGE(""https://docs.google.com/spreadsheets/d/1gLpPUzQ6EQrHHuWolLqit33_eZphYiBD3L5nHSJQQTw"",""Cisco!A1:D1000"")"),"Devices") -> Devices | B1: =IFERROR(__xludf.DUMMYFUNCTION("""COMPUTED_VALUE"""),"List Price") -> List Price | C1: =IFERROR(__xludf.DUMMYFUNCTION("""COMPUTED_VALUE"""),"Giá AM nhập") -> Giá AM nhập | D1: =IFERROR(__xludf.DUMMYFUNCTION("""COMPUTED_VALUE"""),"Final Price") -> Final Price
A2: =IFERROR(__xludf.DUMMYFUNCTION("""COMPUTED_VALUE"""),"C8200L-1N-4T") -> C8200L-1N-4T | B2: =IFERROR(__xludf.DUMMYFUNCTION("""COMPUTED_VALUE"""),22728.05) -> 22728.05 | C2: =IFERROR(__xludf.DUMMYFUNCTION("""COMPUTED_VALUE"""),18000.0) -> 18000 | D2: =IFERROR(__xludf.DUMMYFUNCTION("""COMPUTED_VALUE"""),18000.0) -> 18000
A3: =IFERROR(__xludf.DUMMYFUNCTION("""COMPUTED_VALUE"""),"C8200-1N-4T") -> C8200-1N-4T | B3: =IFERROR(__xludf.DUMMYFUNCTION("""COMPUTED_VALUE"""),29504.46) -> 29504.46 | C3: =IFERROR(__xludf.DUMMYFUNCTION("""COMPUTED_VALUE"""),15000.0) -> 15000 | D3: =IFERROR(__xludf.DUMMYFUNCTION("""COMPUTED_VALUE"""),15000.0) -> 15000
A4: =IFERROR(__xludf.DUMMYFUNCTION("""COMPUTED_VALUE"""),"C8300-2N2S-4T2X") -> C8300-2N2S-4T2X | B4: =IFERROR(__xludf.DUMMYFUNCTION("""COMPUTED_VALUE"""),91782.43) -> 91782.43 | D4: =IFERROR(__xludf.DUMMYFUNCTION("""COMPUTED_VALUE"""),91782.43) -> 91782.43
A5: =IFERROR(__xludf.DUMMYFUNCTION("""COMPUTED_VALUE"""),"C8300-1N1S-4T2X") -> C8300-1N1S-4T2X | B5: =IFERROR(__xludf.DUMMYFUNCTION("""COMPUTED_VALUE"""),75749.61) -> 75749.61 | D5: =IFERROR(__xludf.DUMMYFUNCTION("""COMPUTED_VALUE"""),75749.61) -> 75749.61
A6: =IFERROR(__xludf.DUMMYFUNCTION("""COMPUTED_VALUE"""),"C8300-2N2S-6T") -> C8300-2N2S-6T | B6: =IFERROR(__xludf.DUMMYFUNCTION("""COMPUTED_VALUE"""),50264.61) -> 50264.61 | D6: =IFERROR(__xludf.DUMMYFUNCTION("""COMPUTED_VALUE"""),50264.61) -> 50264.61
A7: =IFERROR(__xludf.DUMMYFUNCTION("""COMPUTED_VALUE"""),"C8300-1N1S-6T") -> C8300-1N1S-6T | B7: =IFERROR(__xludf.DUMMYFUNCTION("""COMPUTED_VALUE"""),41045.93) -> 41045.93 | D7: =IFERROR(__xludf.DUMMYFUNCTION("""COMPUTED_VALUE"""),41045.93) -> 41045.93
A8: =IFERROR(__xludf.DUMMYFUNCTION("""COMPUTED_VALUE"""),"C8500-20X6C") -> C8500-20X6C | B8: =IFERROR(__xludf.DUMMYFUNCTION("""COMPUTED_VALUE"""),553572.06) -> 553572.06 | D8: =IFERROR(__xludf.DUMMYFUNCTION("""COMPUTED_VALUE"""),553572.06) -> 553572.06
A9: =IFERROR(__xludf.DUMMYFUNCTION("""COMPUTED_VALUE"""),"C8500-12X4QC") -> C8500-12X4QC | B9: =IFERROR(__xludf.DUMMYFUNCTION("""COMPUTED_VALUE"""),297234.95) -> 297234.95 | D9: =IFERROR(__xludf.DUMMYFUNCTION("""COMPUTED_VALUE"""),297234.95) -> 297234.95
A10: =IFERROR(__xludf.DUMMYFUNCTION("""COMPUTED_VALUE"""),"C8500-12X") -> C8500-12X | B10: =IFERROR(__xludf.DUMMYFUNCTION("""COMPUTED_VALUE"""),206911.8) -> 206911.8 | C10: =IFERROR(__xludf.DUMMYFUNCTION("""COMPUTED_VALUE"""),1000.0) -> 1000 | D10: =IFERROR(__xludf.DUMMYFUNCTION("""COMPUTED_VALUE"""),1000.0) -> 1000
A11: =IFERROR(__xludf.DUMMYFUNCTION("""COMPUTED_VALUE"""),"C8500L-8S4X") -> C8500L-8S4X | B11: =IFERROR(__xludf.DUMMYFUNCTION("""COMPUTED_VALUE"""),97005.56) -> 97005.56 | D11: =IFERROR(__xludf.DUMMYFUNCTION("""COMPUTED_VALUE"""),97005.56) -> 97005.56
A12: =IFERROR(__xludf.DUMMYFUNCTION("""COMPUTED_VALUE"""),"C9200-24T") -> C9200-24T | B12: =IFERROR(__xludf.DUMMYFUNCTION("""COMPUTED_VALUE"""),9916.42) -> 9916.42 | D12: =IFERROR(__xludf.DUMMYFUNCTION("""COMPUTED_VALUE"""),9916.42) -> 9916.42
A13: =IFERROR(__xludf.DUMMYFUNCTION("""COMPUTED_VALUE"""),"C9200-24P") -> C9200-24P | B13: =IFERROR(__xludf.DUMMYFUNCTION("""COMPUTED_VALUE"""),11052.8) -> 11052.8 | D13: =IFERROR(__xludf.DUMMYFUNCTION("""COMPUTED_VALUE"""),11052.8) -> 11052.8
A14: =IFERROR(__xludf.DUMMYFUNCTION("""COMPUTED_VALUE"""),"C9200-48T") -> C9200-48T | B14: =IFERROR(__xludf.DUMMYFUNCTION("""COMPUTED_VALUE"""),15602.18) -> 15602.18 | D14: =IFERROR(__xludf.DUMMYFUNCTION("""COMPUTED_VALUE"""),15602.18) -> 15602.18
A15: =IFERROR(__xludf.DUMMYFUNCTION("""COMPUTED_VALUE"""),"C9200-48P") -> C9200-48P | B15: =IFERROR(__xludf.DUMMYFUNCTION("""COMPUTED_VALUE"""),19860.05) -> 19860.05 | D15: =IFERROR(__xludf.DUMMYFUNCTION("""COMPUTED_VALUE"""),19860.05) -> 19860.05
A16: =IFERROR(__xludf.DUMMYFUNCTION("""COMPUTED_VALUE"""),"C9200L-24T-4G") -> C9200L-24T-4G | B16: =IFERROR(__xludf.DUMMYFUNCTION("""COMPUTED_VALUE"""),6063.41) -> 6063.41 | D16: =IFERROR(__xludf.DUMMYFUNCTION("""COMPUTED_VALUE"""),6063.41) -> 6063.41
A17: =IFERROR(__xludf.DUMMYFUNCTION("""COMPUTED_VALUE"""),"C9200L-24P-4G") -> C9200L-24P-4G | B17: =IFERROR(__xludf.DUMMYFUNCTION("""COMPUTED_VALUE"""),7529.2) -> 7529.2 | D17: =IFERROR(__xludf.DUMMYFUNCTION("""COMPUTED_VALUE"""),7529.2) -> 7529.2
A18: =IFERROR(__xludf.DUMMYFUNCTION("""COMPUTED_VALUE"""),"C9200L-48T-4G") -> C9200L-48T-4G | B18: =IFERROR(__xludf.DUMMYFUNCTION("""COMPUTED_VALUE"""),10867.95) -> 10867.95 | D18: =IFERROR(__xludf.DUMMYFUNCTION("""COMPUTED_VALUE"""),10867.95) -> 10867.95
A19: =IFERROR(__xludf.DUMMYFUNCTION("""COMPUTED_VALUE"""),"C9200L-48P-4G") -> C9200L-48P-4G | B19: =IFERROR(__xludf.DUMMYFUNCTION("""COMPUTED_VALUE"""),15269.17) -> 15269.17 | D19: =IFERROR(__xludf.DUMMYFUNCTION("""COMPUTED_VALUE"""),15269.17) -> 15269.17
A20: =IFERROR(__xludf.DUMMYFUNCTION("""COMPUTED_VALUE"""),"C9200L-24T-4X") -> C9200L-24T-4X | B20: =IFERROR(__xludf.DUMMYFUNCTION("""COMPUTED_VALUE"""),8631.47) -> 8631.47 | D20: =IFERROR(__xludf.DUMMYFUNCTION("""COMPUTED_VALUE"""),8631.47) -> 8631.47
A21: =IFERROR(__xludf.DUMMYFUNCTION("""COMPUTED_VALUE"""),"C9200L-24P-4X") -> C9200L-24P-4X | B21: =IFERROR(__xludf.DUMMYFUNCTION("""COMPUTED_VALUE"""),10097.26) -> 10097.26 | D21: =IFERROR(__xludf.DUMMYFUNCTION("""COMPUTED_VALUE"""),10097.26) -> 10097.26
A22: =IFERROR(__xludf.DUMMYFUNCTION("""COMPUTED_VALUE"""),"C9200L-48T-4X") -> C9200L-48T-4X | B22: =IFERROR(__xludf.DUMMYFUNCTION("""COMPUTED_VALUE"""),13436.01) -> 13436.01 | D22: =IFERROR(__xludf.DUMMYFUNCTION("""COMPUTED_VALUE"""),13436.01) -> 13436.01
A23: =IFERROR(__xludf.DUMMYFUNCTION("""COMPUTED_VALUE"""),"C9200L-48P-4X") -> C9200L-48P-4X | B23: =IFERROR(__xludf.DUMMYFUNCTION("""COMPUTED_VALUE"""),17837.21) -> 17837.21 | D23: =IFERROR(__xludf.DUMMYFUNCTION("""COMPUTED_VALUE"""),17837.21) -> 17837.21
A24: =IFERROR(__xludf.DUMMYFUNCTION("""COMPUTED_VALUE"""),"C9200CX-8P-2X2G") -> C9200CX-8P-2X2G | B24: =IFERROR(__xludf.DUMMYFUNCTION("""COMPUTED_VALUE"""),5197.72) -> 5197.72 | D24: =IFERROR(__xludf.DUMMYFUNCTION("""COMPUTED_VALUE"""),5197.72) -> 5197.72
A25: =IFERROR(__xludf.DUMMYFUNCTION("""COMPUTED_VALUE"""),"C9200CX-12T-2X2G") -> C9200CX-12T-2X2G | B25: =IFERROR(__xludf.DUMMYFUNCTION("""COMPUTED_VALUE"""),4748.49) -> 4748.49 | D25: =IFERROR(__xludf.DUMMYFUNCTION("""COMPUTED_VALUE"""),4748.49) -> 4748.49
A26: =IFERROR(__xludf.DUMMYFUNCTION("""COMPUTED_VALUE"""),"C9200CX-12P-2X2G") -> C9200CX-12P-2X2G | B26: =IFERROR(__xludf.DUMMYFUNCTION("""COMPUTED_VALUE"""),5672.87) -> 5672.87 | D26: =IFERROR(__xludf.DUMMYFUNCTION("""COMPUTED_VALUE"""),5672.87) -> 5672.87
A27: =IFERROR(__xludf.DUMMYFUNCTION("""COMPUTED_VALUE"""),"C9300L-24T-4G") -> C9300L-24T-4G | B27: =IFERROR(__xludf.DUMMYFUNCTION("""COMPUTED_VALUE"""),13699.63) -> 13699.63 | D27: =IFERROR(__xludf.DUMMYFUNCTION("""COMPUTED_VALUE"""),13699.63) -> 13699.63
